Workbook

Sheet Read Me
A1: AmphenolCIT S/4HANA - Tech Debt & Innovation Planner
A2: Companion to the strategy deck and quick reference guide. Draft v0.1 - Enterprise Architecture.
A4: How to use
A5: 1. Settings | B5: Set day rate, working days, availability and plan start date.
A6: 2. Tech Debt Register | B6: Single backlog for ALL work types. Log every item with the quick reference guide fields. EX-### rows are illustrative - overwrite them.
A7: 3. Score | B7: Business Value, Time Criticality, Risk Reduction/Opportunity Enablement and Job Size on 1-2-3-5-8-13-20. WSJF and rank calculate automatically. P1/P2 defects bypass ranking (expedite lane).
A8: 4. Capacity & Budget | B8: Enter FTE and budget caps; set % allocation per work type per quarter. Compare guardrail capacity to live demand from the register.
A9: 5. Roadmap | B9: Adjust start/end dates; Gantt bars redraw.
A10: 6. Sprint Tracker | B10: Record planned vs done points per type each sprint to show real flow distribution.
A11: 7. KPI Dashboard | B11: Live backlog counts and health signals; update 'Current' KPI values monthly for the portfolio review.
A12: 8. Cadence | B12: The ceremonies that keep grooming and repetition going.
A14: Colour legend
A15: Yellow fill, blue text | B15: Input - edit these
A16: Grey fill | B16: Formula - do not overwrite
A17: Red highlight | B17: Needs attention (stale item, P1/P2, over budget, allocation not 100%)
A19: Definitions
A20: Tech Debt | B20: Something built or configured that works today but increases the cost or risk of future change (e.g. modifications, Z-fields holding standard data, P2P interfaces, missing tests).
A21: Defect | B21: Something that does not work as designed. Severity P1-P4.
A22: Feature | B22: New or improved business capability (e.g. a Fiori app, Work Zone site, new S/4 functionality).
A23: Enabler | B23: Platform / architecture work that makes features possible (e.g. Work Zone subaccount, Integration Suite landing zone, test automation).
A24: Risk/Compliance | B24: Security, audit, maintenance-deadline or licence-driven work.
A25: Interest vs Principal | B25: Interest = recurring cost of living with the debt (hrs/month). Principal = one-off cost to remove it. High interest + low principal = pay down first.

Sheet KPI Dashboard
A1: Visible Progress - KPI Dashboard
A2: Backlog counts update live from the register. KPI baselines/targets are inputs to agree with leadership.
A4: Backlog by type and status (live)
A5: Item type | B5: New | C5: Triaged | D5: Ready | E5: In Progress | F5: Testing | G5: Done | H5: Open total | I5: Open effort (p-days) | J5: Avg WSJF (open)
A6: Feature | B6: =COUNTIFS('Tech Debt Register'!$C$5:$C$204,$A6,'Tech Debt Register'!$X$5:$X$204,"New") -> 3 | C6: =COUNTIFS('Tech Debt Register'!$C$5:$C$204,$A6,'Tech Debt Register'!$X$5:$X$204,"Triaged") -> 0 | D6: =COUNTIFS('Tech Debt Register'!$C$5:$C$204,$A6,'Tech Debt Register'!$X$5:$X$204,"Ready") -> 1 | E6: =COUNTIFS('Tech Debt Register'!$C$5:$C$204,$A6,'Tech Debt Register'!$X$5:$X$204,"In Progress") -> 0 | F6: =COUNTIFS('Tech Debt Register'!$C$5:$C$204,$A6,'Tech Debt Register'!$X$5:$X$204,"Testing") -> 0 | G6: =COUNTIFS('Tech Debt Register'!$C$5:$C$204,$A6,'Tech Debt Register'!$X$5:$X$204,"Done") -> 0 | H6: =SUM(B6:F6) -> 4 | I6: =SUMIFS('Tech Debt Register'!$R$5:$R$204,'Tech Debt Register'!$C$5:$C$204,$A6,'Tech Debt Register'!$X$5:$X$204,"<>Done",'Tech Debt Register'!$X$5:$X$204,"<>Rejected") -> 50 | J6: =IFERROR(AVERAGEIFS('Tech Debt Register'!$O$5:$O$204,'Tech Debt Register'!$C$5:$C$204,$A6,'Tech Debt Register'!$X$5:$X$204,"<>Done",'Tech Debt Register'!$X$5:$X$204,"<>Rejected"),"") -> 5.125
A7: Defect | B7: =COUNTIFS('Tech Debt Register'!$C$5:$C$204,$A7,'Tech Debt Register'!$X$5:$X$204,"New") -> 1 | C7: =COUNTIFS('Tech Debt Register'!$C$5:$C$204,$A7,'Tech Debt Register'!$X$5:$X$204,"Triaged") -> 0 | D7: =COUNTIFS('Tech Debt Register'!$C$5:$C$204,$A7,'Tech Debt Register'!$X$5:$X$204,"Ready") -> 0 | E7: =COUNTIFS('Tech Debt Register'!$C$5:$C$204,$A7,'Tech Debt Register'!$X$5:$X$204,"In Progress") -> 2 | F7: =COUNTIFS('Tech Debt Register'!$C$5:$C$204,$A7,'Tech Debt Register'!$X$5:$X$204,"Testing") -> 0 | G7: =COUNTIFS('Tech Debt Register'!$C$5:$C$204,$A7,'Tech Debt Register'!$X$5:$X$204,"Done") -> 0 | H7: =SUM(B7:F7) -> 3 | I7: =SUMIFS('Tech Debt Register'!$R$5:$R$204,'Tech Debt Register'!$C$5:$C$204,$A7,'Tech Debt Register'!$X$5:$X$204,"<>Done",'Tech Debt Register'!$X$5:$X$204,"<>Rejected") -> 8 | J7: =IFERROR(AVERAGEIFS('Tech Debt Register'!$O$5:$O$204,'Tech Debt Register'!$C$5:$C$204,$A7,'Tech Debt Register'!$X$5:$X$204,"<>Done",'Tech Debt Register'!$X$5:$X$204,"<>Rejected"),"") -> 8.8333333
A8: Tech Debt | B8: =COUNTIFS('Tech Debt Register'!$C$5:$C$204,$A8,'Tech Debt Register'!$X$5:$X$204,"New") -> 2 | C8: =COUNTIFS('Tech Debt Register'!$C$5:$C$204,$A8,'Tech Debt Register'!$X$5:$X$204,"Triaged") -> 4 | D8: =COUNTIFS('Tech Debt Register'!$C$5:$C$204,$A8,'Tech Debt Register'!$X$5:$X$204,"Ready") -> 1 | E8: =COUNTIFS('Tech Debt Register'!$C$5:$C$204,$A8,'Tech Debt Register'!$X$5:$X$204,"In Progress") -> 0 | F8: =COUNTIFS('Tech Debt Register'!$C$5:$C$204,$A8,'Tech Debt Register'!$X$5:$X$204,"Testing") -> 0 | G8: =COUNTIFS('Tech Debt Register'!$C$5:$C$204,$A8,'Tech Debt Register'!$X$5:$X$204,"Done") -> 0 | H8: =SUM(B8:F8) -> 7 | I8: =SUMIFS('Tech Debt Register'!$R$5:$R$204,'Tech Debt Register'!$C$5:$C$204,$A8,'Tech Debt Register'!$X$5:$X$204,"<>Done",'Tech Debt Register'!$X$5:$X$204,"<>Rejected") -> 188 | J8: =IFERROR(AVERAGEIFS('Tech Debt Register'!$O$5:$O$204,'Tech Debt Register'!$C$5:$C$204,$A8,'Tech Debt Register'!$X$5:$X$204,"<>Done",'Tech Debt Register'!$X$5:$X$204,"<>Rejected"),"") -> 3.2285714
A9: Enabler | B9: =COUNTIFS('Tech Debt Register'!$C$5:$C$204,$A9,'Tech Debt Register'!$X$5:$X$204,"New") -> 2 | C9: =COUNTIFS('Tech Debt Register'!$C$5:$C$204,$A9,'Tech Debt Register'!$X$5:$X$204,"Triaged") -> 0 | D9: =COUNTIFS('Tech Debt Register'!$C$5:$C$204,$A9,'Tech Debt Register'!$X$5:$X$204,"Ready") -> 2 | E9: =COUNTIFS('Tech Debt Register'!$C$5:$C$204,$A9,'Tech Debt Register'!$X$5:$X$204,"In Progress") -> 0 | F9: =COUNTIFS('Tech Debt Register'!$C$5:$C$204,$A9,'Tech Debt Register'!$X$5:$X$204,"Testing") -> 0 | G9: =COUNTIFS('Tech Debt Register'!$C$5:$C$204,$A9,'Tech Debt Register'!$X$5:$X$204,"Done") -> 0 | H9: =SUM(B9:F9) -> 4 | I9: =SUMIFS('Tech Debt Register'!$R$5:$R$204,'Tech Debt Register'!$C$5:$C$204,$A9,'Tech Debt Register'!$X$5:$X$204,"<>Done",'Tech Debt Register'!$X$5:$X$204,"<>Rejected") -> 97 | J9: =IFERROR(AVERAGEIFS('Tech Debt Register'!$O$5:$O$204,'Tech Debt Register'!$C$5:$C$204,$A9,'Tech Debt Register'!$X$5:$X$204,"<>Done",'Tech Debt Register'!$X$5:$X$204,"<>Rejected"),"") -> 3.8
A10: Risk/Compliance | B10: =COUNTIFS('Tech Debt Register'!$C$5:$C$204,$A10,'Tech Debt Register'!$X$5:$X$204,"New") -> 1 | C10: =COUNTIFS('Tech Debt Register'!$C$5:$C$204,$A10,'Tech Debt Register'!$X$5:$X$204,"Triaged") -> 1 | D10: =COUNTIFS('Tech Debt Register'!$C$5:$C$204,$A10,'Tech Debt Register'!$X$5:$X$204,"Ready") -> 0 | E10: =COUNTIFS('Tech Debt Register'!$C$5:$C$204,$A10,'Tech Debt Register'!$X$5:$X$204,"In Progress") -> 0 | F10: =COUNTIFS('Tech Debt Register'!$C$5:$C$204,$A10,'Tech Debt Register'!$X$5:$X$204,"Testing") -> 0 | G10: =COUNTIFS('Tech Debt Register'!$C$5:$C$204,$A10,'Tech Debt Register'!$X$5:$X$204,"Done") -> 0 | H10: =SUM(B10:F10) -> 2 | I10: =SUMIFS('Tech Debt Register'!$R$5:$R$204,'Tech Debt Register'!$C$5:$C$204,$A10,'Tech Debt Register'!$X$5:$X$204,"<>Done",'Tech Debt Register'!$X$5:$X$204,"<>Rejected") -> 55 | J10: =IFERROR(AVERAGEIFS('Tech Debt Register'!$O$5:$O$204,'Tech Debt Register'!$C$5:$C$204,$A10,'Tech Debt Register'!$X$5:$X$204,"<>Done",'Tech Debt Register'!$X$5:$X$204,"<>Rejected"),"") -> 3.7
A11: Total | B11: =SUM(B6:B10) -> 9 | C11: =SUM(C6:C10) -> 5 | D11: =SUM(D6:D10) -> 4 | E11: =SUM(E6:E10) -> 2 | F11: =SUM(F6:F10) -> 0 | G11: =SUM(G6:G10) -> 0 | H11: =SUM(H6:H10) -> 20 | I11: =SUM(I6:I10) -> 398
A13: Health signals (live)
A14: Stale items (New/Triaged > threshold) | E14: =COUNTIF('Tech Debt Register'!$AC$5:$AC$204,"STALE") -> 1
A15: Open items blocking innovation | E15: =COUNTIFS('Tech Debt Register'!$I$5:$I$204,"Y",'Tech Debt Register'!$X$5:$X$204,"<>Done",'Tech Debt Register'!$X$5:$X$204,"<>Rejected") -> 10
A16: Open Level C/D clean-core items | E16: =COUNTIFS('Tech Debt Register'!$H$5:$H$204,"C",'Tech Debt Register'!$X$5:$X$204,"<>Done")+COUNTIFS('Tech Debt Register'!$H$5:$H$204,"D",'Tech Debt Register'!$X$5:$X$204,"<>Done") -> 5
A17: Open P1/P2 defects | E17: =COUNTIFS('Tech Debt Register'!$J$5:$J$204,"P1",'Tech Debt Register'!$X$5:$X$204,"<>Done")+COUNTIFS('Tech Debt Register'!$J$5:$J$204,"P2",'Tech Debt Register'!$X$5:$X$204,"<>Done") -> 1
A18: Annual interest cost of open tech debt (USD) | E18: =SUMIFS('Tech Debt Register'!$T$5:$T$204,'Tech Debt Register'!$C$5:$C$204,"Tech Debt",'Tech Debt Register'!$X$5:$X$204,"<>Done") -> 163125
A19: Open tech debt principal (USD) | E19: =SUMIFS('Tech Debt Register'!$S$5:$S$204,'Tech Debt Register'!$C$5:$C$204,"Tech Debt",'Tech Debt Register'!$X$5:$X$204,"<>Done") -> 141000
A22: Outcome KPIs (agree baseline + targets; update 'Current' monthly)
A23: KPI | B23: Dimension | C23: Unit | D23: Baseline | E23: Target Q2-2027 | F23: Target Q4-2027 | G23: Current | H23: Direction | I23: RAG | J23: Source / tool
A24: Share of active users launching Fiori apps monthly | B24: UX | C24: % | D24: 0 | E24: 0.4 | F24: 0.75 | H24: Up | I24: =IF(G24="","Not measured",IF(H24="Up",IF(G24>=E24,"G",IF(G24>D24,"A","R")),IF(H24="Down",IF(G24<=E24,"G",IF(G24<D24,"A","R")),IF(ABS(G24-E24)<=0.05*MAX(ABS(E24),1),"G","A")))) -> Not measured
A25: Fiori apps in productive use | B25: UX | C25: # | D25: 0 | E25: 40 | F25: 120 | H25: Up | I25: =IF(G25="","Not measured",IF(H25="Up",IF(G25>=E25,"G",IF(G25>D25,"A","R")),IF(H25="Down",IF(G25<=E25,"G",IF(G25<D25,"A","R")),IF(ABS(G25-E25)<=0.05*MAX(ABS(E25),1),"G","A")))) -> Not measured
A26: Users onboarded to Work Zone sites | B26: UX | C26: # | D26: 0 | E26: 150 | F26: 600 | H26: Up | I26: =IF(G26="","Not measured",IF(H26="Up",IF(G26>=E26,"G",IF(G26>D26,"A","R")),IF(H26="Down",IF(G26<=E26,"G",IF(G26<D26,"A","R")),IF(ABS(G26-E26)<=0.05*MAX(ABS(E26),1),"G","A")))) -> Not measured
A27: Interfaces on Integration Suite (of total) | B27: Integration | C27: % | D27: 0.05 | E27: 0.35 | F27: 0.7 | H27: Up | I27: =IF(G27="","Not measured",IF(H27="Up",IF(G27>=E27,"G",IF(G27>D27,"A","R")),IF(H27="Down",IF(G27<=E27,"G",IF(G27<D27,"A","R")),IF(ABS(G27-E27)<=0.05*MAX(ABS(E27),1),"G","A")))) -> Not measured
A28: Interface failures per month | B28: Integration | C28: # | D28: 120 | E28: 60 | F28: 20 | H28: Down | I28: =IF(G28="","Not measured",IF(H28="Up",IF(G28>=E28,"G",IF(G28>D28,"A","R")),IF(H28="Down",IF(G28<=E28,"G",IF(G28<D28,"A","R")),IF(ABS(G28-E28)<=0.05*MAX(ABS(E28),1),"G","A")))) -> Not measured
A29: Custom objects (Z) in use | B29: Extensibility | C29: # | D29: 2500 | E29: 2000 | F29: 1600 | H29: Down | I29: =IF(G29="","Not measured",IF(H29="Up",IF(G29>=E29,"G",IF(G29>D29,"A","R")),IF(H29="Down",IF(G29<=E29,"G",IF(G29<D29,"A","R")),IF(ABS(G29-E29)<=0.05*MAX(ABS(E29),1),"G","A")))) -> Not measured
A30: ATC clean-core findings Level C/D | B30: Extensibility | C30: # | D30: 900 | E30: 700 | F30: 450 | H30: Down | I30: =IF(G30="","Not measured",IF(H30="Up",IF(G30>=E30,"G",IF(G30>D30,"A","R")),IF(H30="Down",IF(G30<=E30,"G",IF(G30<D30,"A","R")),IF(ABS(G30-E30)<=0.05*MAX(ABS(E30),1),"G","A")))) -> Not measured
A31: Business-data custom fields mapped to standard or exposed | B31: Data | C31: % | D31: 0 | E31: 0.5 | F31: 0.9 | H31: Up | I31: =IF(G31="","Not measured",IF(H31="Up",IF(G31>=E31,"G",IF(G31>D31,"A","R")),IF(H31="Down",IF(G31<=E31,"G",IF(G31<D31,"A","R")),IF(ABS(G31-E31)<=0.05*MAX(ABS(E31),1),"G","A")))) -> Not measured
A32: Master data quality score (rule pass rate) | B32: Data | C32: % | D32: 0.72 | E32: 0.85 | F32: 0.95 | H32: Up | I32: =IF(G32="","Not measured",IF(H32="Up",IF(G32>=E32,"G",IF(G32>D32,"A","R")),IF(H32="Down",IF(G32<=E32,"G",IF(G32<D32,"A","R")),IF(ABS(G32-E32)<=0.05*MAX(ABS(E32),1),"G","A")))) -> Not measured
A33: Median lead time request -> production (days) | B33: Operations | C33: days | D33: 45 | E33: 30 | F33: 20 | H33: Down | I33: =IF(G33="","Not measured",IF(H33="Up",IF(G33>=E33,"G",IF(G33>D33,"A","R")),IF(H33="Down",IF(G33<=E33,"G",IF(G33<D33,"A","R")),IF(ABS(G33-E33)<=0.05*MAX(ABS(E33),1),"G","A")))) -> Not measured
A34: Tech debt share of delivered capacity | B34: Operations | C34: % | D34: 0.05 | E34: 0.25 | F34: 0.2 | H34: Hold | I34: =IF(G34="","Not measured",IF(H34="Up",IF(G34>=E34,"G",IF(G34>D34,"A","R")),IF(H34="Down",IF(G34<=E34,"G",IF(G34<D34,"A","R")),IF(ABS(G34-E34)<=0.05*MAX(ABS(E34),1),"G","A")))) -> Not measured
A35: Behind latest S/4 FPS / release (months) | B35: Operations | C35: months | D35: 12 | E35: 12 | F35: 3 | H35: Down | I35: =IF(G35="","Not measured",IF(H35="Up",IF(G35>=E35,"G",IF(G35>D35,"A","R")),IF(H35="Down",IF(G35<=E35,"G",IF(G35<D35,"A","R")),IF(ABS(G35-E35)<=0.05*MAX(ABS(E35),1),"G","A")))) -> Not measured
A37: Baselines/targets are illustrative placeholders; RAG compares Current to the Q2-2027 target (G = met, A = improving vs baseline, R = not improving).

Sheet Tech Debt Register
A1: Unified Backlog & Tech Debt Register
A2: One backlog for Features, Defects, Tech Debt, Enablers and Risk/Compliance. Yellow = input; grey = calculated. Rows EX-### are ILLUSTRATIVE - overwrite with real items.
A4: ID | B4: Title | C4: Item Type | D4: Clean Core Dimension | E4: Area / Module | F4: Description / symptom | G4: Root cause (Fowler quadrant) | H4: Clean Core Level (A-D) | I4: Blocks innovation? (Y/N) | J4: Bug severity (P1-P4) | K4: Business Value | L4: Time Criticality | M4: Risk Reduction / Opportunity Enablement | N4: Job Size | O4: WSJF score | P4: Priority rank | Q4: Interest (hrs / month lost) | R4: Principal (effort person-days) | S4: Est. cost (USD) | T4: Annual interest cost (USD) | U4: Payback (months) | V4: Business owner | W4: IT owner | X4: Status | Y4: Target quarter | Z4: Date raised | AA4: Date closed | AB4: Age (days) | AC4: Stale? | AD4: Notes / evidence link
A5: EX-001 | B5: Business data held in custom Z-fields on material master (MARA append) | C5: Tech Debt | D5: Data | E5: MM | F5: Z-fields not exposed via CDS/OData; standard Fiori apps, APIs and analytics cannot see the data. Users revert to SE16N/Excel. | G5: Deliberate-Prudent | H5: C | I5: Y | J5: n/a | K5: 13 | L5: 8 | M5: 13 | N5: 8 | O5: =IF(OR(N5="",N5=0),"",ROUND((K5+L5+M5)/N5,1)) -> 4.3 | P5: =IF(OR(O5="",X5="Done",X5="Rejected"),"",COUNTIFS($O$5:$O$204,">"&O5,$X$5:$X$204,"<>Done",$X$5:$X$204,"<>Rejected")+1) -> 10 | Q5: 40 | R5: 25 | S5: =IF(R5="","",R5*Settings!$B$5) -> 18750 | T5: =IF(Q5="","",Q5*12*Settings!$B$5/8) -> 45000 | U5: =IF(OR(S5="",T5="",T5=0),"",ROUND(S5/(T5/12),1)) -> 5 | V5: Materials Mgmt lead | W5: MM functional lead | X5: Triaged | Y5: Q1-2027 | Z5: 46266 | AB5: =IF(Z5="","",IF(AA5="",TODAY(),AA5)-Z5) -> 26 | AC5: =IF(AB5="","",IF(AND(OR(X5="New",X5="Triaged"),AB5>Settings!$B$9),"STALE","")) | AD5: Evidence: SE11 append ZAMARA; map each Z-field to standard field or Custom Fields app
A6: EX-002 | B6: Activate Fiori launchpad + role-based spaces for AP / AR clerks | C6: Feature | D6: UX | E6: FI | F6: Finance users on SAP GUI only; Manage Supplier Line Items, Clear GL Accounts etc. not in use. | G6: n/a | H6: A | I6: N | J6: n/a | K6: 13 | L6: 5 | M6: 8 | N6: 5 | O6: =IF(OR(N6="",N6=0),"",ROUND((K6+L6+M6)/N6,1)) -> 5.2 | P6: =IF(OR(O6="",X6="Done",X6="Rejected"),"",COUNTIFS($O$5:$O$204,">"&O6,$X$5:$X$204,"<>Done",$X$5:$X$204,"<>Rejected")+1) -> 5 | Q6: 20 | R6: 15 | S6: =IF(R6="","",R6*Settings!$B$5) -> 11250 | T6: =IF(Q6="","",Q6*12*Settings!$B$5/8) -> 22500 | U6: =IF(OR(S6="",T6="",T6=0),"",ROUND(S6/(T6/12),1)) -> 6 | V6: Finance controller | W6: Fiori/Basis lead | X6: Ready | Y6: Q4-2026 | Z6: 46270 | AB6: =IF(Z6="","",IF(AA6="",TODAY(),AA6)-Z6) -> 22 | AC6: =IF(AB6="","",IF(AND(OR(X6="New",X6="Triaged"),AB6>Settings!$B$9),"STALE","")) | AD6: Use Fiori Apps Library recommendations report from ST03N usage
A7: EX-003 | B7: SAP Build Work Zone (standard) subaccount, IdP and content federation | C7: Enabler | D7: UX | E7: BTP | F7: No central entry point; users bookmark GUI transactions and separate portals. | G7: n/a | H7: A | I7: Y | J7: n/a | K7: 8 | L7: 5 | M7: 13 | N7: 5 | O7: =IF(OR(N7="",N7=0),"",ROUND((K7+L7+M7)/N7,1)) -> 5.2 | P7: =IF(OR(O7="",X7="Done",X7="Rejected"),"",COUNTIFS($O$5:$O$204,">"&O7,$X$5:$X$204,"<>Done",$X$5:$X$204,"<>Rejected")+1) -> 5 | Q7: 0 | R7: 20 | S7: =IF(R7="","",R7*Settings!$B$5) -> 15000 | T7: =IF(Q7="","",Q7*12*Settings!$B$5/8) -> 0 | U7: =IF(OR(S7="",T7="",T7=0),"",ROUND(S7/(T7/12),1)) | V7: CIO office | W7: BTP platform lead | X7: Ready | Y7: Q4-2026 | Z7: 46270 | AB7: =IF(Z7="","",IF(AA7="",TODAY(),AA7)-Z7) -> 22 | AC7: =IF(AB7="","",IF(AND(OR(X7="New",X7="Triaged"),AB7>Settings!$B$9),"STALE","")) | AD7: Prereq: SAP Cloud Identity Services, Cloud Connector, content provider from S/4 FLP
A8: EX-004 | B8: Point-to-point RFC / file interfaces to MES re-platformed to Integration Suite | C8: Tech Debt | D8: Integration | E8: Integration | F8: 12 custom RFC/file jobs, no monitoring, failures found by users. | G8: Inadvertent-Prudent | H8: B | I8: Y | J8: n/a | K8: 8 | L8: 5 | M8: 13 | N8: 13 | O8: =IF(OR(N8="",N8=0),"",ROUND((K8+L8+M8)/N8,1)) -> 2 | P8: =IF(OR(O8="",X8="Done",X8="Rejected"),"",COUNTIFS($O$5:$O$204,">"&O8,$X$5:$X$204,"<>Done",$X$5:$X$204,"<>Rejected")+1) -> 18 | Q8: 30 | R8: 60 | S8: =IF(R8="","",R8*Settings!$B$5) -> 45000 | T8: =IF(Q8="","",Q8*12*Settings!$B$5/8) -> 33750 | U8: =IF(OR(S8="",T8="",T8=0),"",ROUND(S8/(T8/12),1)) -> 16 | V8: Plant ops director | W8: Integration lead | X8: New | Y8: Q2-2027 | Z8: 46275 | AB8: =IF(Z8="","",IF(AA8="",TODAY(),AA8)-Z8) -> 17 | AC8: =IF(AB8="","",IF(AND(OR(X8="New",X8="Triaged"),AB8>Settings!$B$9),"STALE","")) | AD8: Run Integration Suite Migration Assessment + ISA-M classification
A9: EX-005 | B9: Intercompany STO pricing condition wrong for plant 2100 | C9: Defect | D9: Process | E9: SD | F9: Wrong transfer price on intercompany billing; manual correction each month-end. | G9: Inadvertent-Reckless | H9: n/a | I9: N | J9: P3 | K9: 5 | L9: 8 | M9: 5 | N9: 2 | O9: =IF(OR(N9="",N9=0),"",ROUND((K9+L9+M9)/N9,1)) -> 9 | P9: =IF(OR(O9="",X9="Done",X9="Rejected"),"",COUNTIFS($O$5:$O$204,">"&O9,$X$5:$X$204,"<>Done",$X$5:$X$204,"<>Rejected")+1) -> 2 | Q9: 16 | R9: 3 | S9: =IF(R9="","",R9*Settings!$B$5) -> 2250 | T9: =IF(Q9="","",Q9*12*Settings!$B$5/8) -> 18000 | U9: =IF(OR(S9="",T9="",T9=0),"",ROUND(S9/(T9/12),1)) -> 1.5 | V9: Sales ops | W9: SD functional lead | X9: In Progress | Y9: Q4-2026 | Z9: 46254 | AB9: =IF(Z9="","",IF(AA9="",TODAY(),AA9)-Z9) -> 38 | AC9: =IF(AB9="","",IF(AND(OR(X9="New",X9="Triaged"),AB9>Settings!$B$9),"STALE",""))
A10: EX-006 | B10: Modifications in sales-order user exits (MV45AFZZ) refactored to released BAdIs | C10: Tech Debt | D10: Extensibility | E10: SD | F10: Implicit enhancements + modifications slow every upgrade and block clean core. | G10: Deliberate-Reckless | H10: D | I10: Y | J10: n/a | K10: 5 | L10: 3 | M10: 13 | N10: 8 | O10: =IF(OR(N10="",N10=0),"",ROUND((K10+L10+M10)/N10,1)) -> 2.6 | P10: =IF(OR(O10="",X10="Done",X10="Rejected"),"",COUNTIFS($O$5:$O$204,">"&O10,$X$5:$X$204,"<>Done",$X$5:$X$204,"<>Rejected")+1) -> 15 | Q10: 12 | R10: 30 | S10: =IF(R10="","",R10*Settings!$B$5) -> 22500 | T10: =IF(Q10="","",Q10*12*Settings!$B$5/8) -> 13500 | U10: =IF(OR(S10="",T10="",T10=0),"",ROUND(S10/(T10/12),1)) -> 20 | V10: Sales ops | W10: ABAP dev lead | X10: Triaged | Y10: Q2-2027 | Z10: 46277 | AB10: =IF(Z10="","",IF(AA10="",TODAY(),AA10)-Z10) -> 15 | AC10: =IF(AB10="","",IF(AND(OR(X10="New",X10="Triaged"),AB10>Settings!$B$9),"STALE","")) | AD10: ATC clean-core check variant findings
A11: EX-007 | B11: Decommission unused custom code (no usage in 12 months) | C11: Tech Debt | D11: Extensibility | E11: Cross-app | F11: Approx. 30% of Z-objects show no execution in SCMON/SUSG data. | G11: Inadvertent-Prudent | H11: C | I11: N | J11: n/a | K11: 3 | L11: 2 | M11: 8 | N11: 3 | O11: =IF(OR(N11="",N11=0),"",ROUND((K11+L11+M11)/N11,1)) -> 4.3 | P11: =IF(OR(O11="",X11="Done",X11="Rejected"),"",COUNTIFS($O$5:$O$204,">"&O11,$X$5:$X$204,"<>Done",$X$5:$X$204,"<>Rejected")+1) -> 10 | Q11: 8 | R11: 10 | S11: =IF(R11="","",R11*Settings!$B$5) -> 7500 | T11: =IF(Q11="","",Q11*12*Settings!$B$5/8) -> 9000 | U11: =IF(OR(S11="",T11="",T11=0),"",ROUND(S11/(T11/12),1)) -> 10 | V11: CIO office | W11: ABAP dev lead | X11: Triaged | Y11: Q1-2027 | Z11: 46277 | AB11: =IF(Z11="","",IF(AA11="",TODAY(),AA11)-Z11) -> 15 | AC11: =IF(AB11="","",IF(AND(OR(X11="New",X11="Triaged"),AB11>Settings!$B$9),"STALE","")) | AD11: Custom Code Migration app scoping; retire before remediate
A12: EX-008 | B12: Adopt Monitor Material Coverage / MRP Live Fiori apps for planners | C12: Feature | D12: Process | E12: PP | F12: Planners use MD04 + Excel; exception-based planning not used. | G12: n/a | H12: A | I12: N | J12: n/a | K12: 13 | L12: 5 | M12: 5 | N12: 5 | O12: =IF(OR(N12="",N12=0),"",ROUND((K12+L12+M12)/N12,1)) -> 4.6 | P12: =IF(OR(O12="",X12="Done",X12="Rejected"),"",COUNTIFS($O$5:$O$204,">"&O12,$X$5:$X$204,"<>Done",$X$5:$X$204,"<>Rejected")+1) -> 9 | Q12: 25 | R12: 15 | S12: =IF(R12="","",R12*Settings!$B$5) -> 11250 | T12: =IF(Q12="","",Q12*12*Settings!$B$5/8) -> 28125 | U12: =IF(OR(S12="",T12="",T12=0),"",ROUND(S12/(T12/12),1)) -> 4.8 | V12: Supply chain VP | W12: PP functional lead | X12: New | Y12: Q1-2027 | Z12: 46280 | AB12: =IF(Z12="","",IF(AA12="",TODAY(),AA12)-Z12) -> 12 | AC12: =IF(AB12="","",IF(AND(OR(X12="New",X12="Triaged"),AB12>Settings!$B$9),"STALE",""))
A13: EX-009 | B13: S/4HANA Feature Pack / release currency plan | C13: Risk/Compliance | D13: Operations | E13: Basis | F13: System behind latest FPS; missing innovations and security fixes. | G13: Deliberate-Prudent | H13: n/a | I13: Y | J13: n/a | K13: 8 | L13: 8 | M13: 13 | N13: 13 | O13: =IF(OR(N13="",N13=0),"",ROUND((K13+L13+M13)/N13,1)) -> 2.2 | P13: =IF(OR(O13="",X13="Done",X13="Rejected"),"",COUNTIFS($O$5:$O$204,">"&O13,$X$5:$X$204,"<>Done",$X$5:$X$204,"<>Rejected")+1) -> 17 | Q13: 0 | R13: 45 | S13: =IF(R13="","",R13*Settings!$B$5) -> 33750 | T13: =IF(Q13="","",Q13*12*Settings!$B$5/8) -> 0 | U13: =IF(OR(S13="",T13="",T13=0),"",ROUND(S13/(T13/12),1)) | V13: CIO office | W13: Basis lead | X13: New | Y13: Q2-2027 | Z13: 46280 | AB13: =IF(Z13="","",IF(AA13="",TODAY(),AA13)-Z13) -> 12 | AC13: =IF(AB13="","",IF(AND(OR(X13="New",X13="Triaged"),AB13>Settings!$B$9),"STALE","")) | AD13: Run SAP Readiness Check for the target release
A14: EX-010 | B14: Duplicate business partners (customer/supplier) cleansing | C14: Tech Debt | D14: Data | E14: Cross-app | F14: Estimated duplicates cause blocked payments and credit errors. | G14: Inadvertent-Reckless | H14: n/a | I14: Y | J14: n/a | K14: 8 | L14: 5 | M14: 8 | N14: 8 | O14: =IF(OR(N14="",N14=0),"",ROUND((K14+L14+M14)/N14,1)) -> 2.6 | P14: =IF(OR(O14="",X14="Done",X14="Rejected"),"",COUNTIFS($O$5:$O$204,">"&O14,$X$5:$X$204,"<>Done",$X$5:$X$204,"<>Rejected")+1) -> 15 | Q14: 30 | R14: 25 | S14: =IF(R14="","",R14*Settings!$B$5) -> 18750 | T14: =IF(Q14="","",Q14*12*Settings!$B$5/8) -> 33750 | U14: =IF(OR(S14="",T14="",T14=0),"",ROUND(S14/(T14/12),1)) -> 6.7 | V14: Master data owner | W14: Data lead | X14: Triaged | Y14: Q1-2027 | Z14: 46266 | AB14: =IF(Z14="","",IF(AA14="",TODAY(),AA14)-Z14) -> 26 | AC14: =IF(AB14="","",IF(AND(OR(X14="New",X14="Triaged"),AB14>Settings!$B$9),"STALE","")) | AD14: Profile with Data Quality rules; evaluate SAP MDG consolidation
A15: EX-011 | B15: ORDERS IDoc failures from EDI partner | C15: Defect | D15: Integration | E15: SD | F15: Status 51 errors daily; orders re-keyed manually. | G15: Inadvertent-Prudent | H15: n/a | I15: N | J15: P2 | K15: 8 | L15: 13 | M15: 8 | N15: 2 | O15: =IF(OR(N15="",N15=0),"",ROUND((K15+L15+M15)/N15,1)) -> 14.5 | P15: =IF(OR(O15="",X15="Done",X15="Rejected"),"",COUNTIFS($O$5:$O$204,">"&O15,$X$5:$X$204,"<>Done",$X$5:$X$204,"<>Rejected")+1) -> 1 | Q15: 20 | R15: 4 | S15: =IF(R15="","",R15*Settings!$B$5) -> 3000 | T15: =IF(Q15="","",Q15*12*Settings!$B$5/8) -> 22500 | U15: =IF(OR(S15="",T15="",T15=0),"",ROUND(S15/(T15/12),1)) -> 1.6 | V15: Customer service | W15: Integration lead | X15: In Progress | Y15: Q4-2026 | Z15: 46283 | AB15: =IF(Z15="","",IF(AA15="",TODAY(),AA15)-Z15) -> 9 | AC15: =IF(AB15="","",IF(AND(OR(X15="New",X15="Triaged"),AB15>Settings!$B$9),"STALE","")) | AD15: BD87
A16: EX-012 | B16: Integration Suite landing zone: naming, transport (cTMS), monitoring in Cloud ALM | C16: Enabler | D16: Integration | E16: BTP | F16: Integration Suite just started; no standards yet, risk of new debt. | G16: n/a | H16: A | I16: Y | J16: n/a | K16: 5 | L16: 8 | M16: 13 | N16: 5 | O16: =IF(OR(N16="",N16=0),"",ROUND((K16+L16+M16)/N16,1)) -> 5.2 | P16: =IF(OR(O16="",X16="Done",X16="Rejected"),"",COUNTIFS($O$5:$O$204,">"&O16,$X$5:$X$204,"<>Done",$X$5:$X$204,"<>Rejected")+1) -> 5 | Q16: 0 | R16: 15 | S16: =IF(R16="","",R16*Settings!$B$5) -> 11250 | T16: =IF(Q16="","",Q16*12*Settings!$B$5/8) -> 0 | U16: =IF(OR(S16="",T16="",T16=0),"",ROUND(S16/(T16/12),1)) | V16: CIO office | W16: Integration lead | X16: Ready | Y16: Q4-2026 | Z16: 46270 | AB16: =IF(Z16="","",IF(AA16="",TODAY(),AA16)-Z16) -> 22 | AC16: =IF(AB16="","",IF(AND(OR(X16="New",X16="Triaged"),AB16>Settings!$B$9),"STALE",""))
A17: EX-013 | B17: Replace custom ALV reports with standard analytical Fiori apps / CDS | C17: Tech Debt | D17: UX | E17: FI | F17: 40+ Z-reports duplicate standard analytics. | G17: Deliberate-Prudent | H17: C | I17: N | J17: n/a | K17: 5 | L17: 2 | M17: 5 | N17: 8 | O17: =IF(OR(N17="",N17=0),"",ROUND((K17+L17+M17)/N17,1)) -> 1.5 | P17: =IF(OR(O17="",X17="Done",X17="Rejected"),"",COUNTIFS($O$5:$O$204,">"&O17,$X$5:$X$204,"<>Done",$X$5:$X$204,"<>Rejected")+1) -> 20 | Q17: 15 | R17: 30 | S17: =IF(R17="","",R17*Settings!$B$5) -> 22500 | T17: =IF(Q17="","",Q17*12*Settings!$B$5/8) -> 16875 | U17: =IF(OR(S17="",T17="",T17=0),"",ROUND(S17/(T17/12),1)) -> 16 | V17: Finance controller | W17: ABAP dev lead | X17: New | Y17: Q3-2027 | Z17: 46285 | AB17: =IF(Z17="","",IF(AA17="",TODAY(),AA17)-Z17) -> 7 | AC17: =IF(AB17="","",IF(AND(OR(X17="New",X17="Triaged"),AB17>Settings!$B$9),"STALE",""))
A18: EX-014 | B18: Work Zone site for plant supervisors (Fiori + non-SAP tiles) | C18: Feature | D18: UX | E18: PP | F18: Supervisors switch between 5 tools per shift. | G18: n/a | H18: A | I18: N | J18: n/a | K18: 8 | L18: 3 | M18: 5 | N18: 5 | O18: =IF(OR(N18="",N18=0),"",ROUND((K18+L18+M18)/N18,1)) -> 3.2 | P18: =IF(OR(O18="",X18="Done",X18="Rejected"),"",COUNTIFS($O$5:$O$204,">"&O18,$X$5:$X$204,"<>Done",$X$5:$X$204,"<>Rejected")+1) -> 12 | Q18: 10 | R18: 15 | S18: =IF(R18="","",R18*Settings!$B$5) -> 11250 | T18: =IF(Q18="","",Q18*12*Settings!$B$5/8) -> 11250 | U18: =IF(OR(S18="",T18="",T18=0),"",ROUND(S18/(T18/12),1)) -> 12 | V18: Plant ops director | W18: BTP platform lead | X18: New | Y18: Q2-2027 | Z18: 46285 | AB18: =IF(Z18="","",IF(AA18="",TODAY(),AA18)-Z18) -> 7 | AC18: =IF(AB18="","",IF(AND(OR(X18="New",X18="Triaged"),AB18>Settings!$B$9),"STALE","")) | AD18: Depends on EX-003
A19: EX-015 | B19: Move transport management to Cloud ALM Change & Deployment | C19: Enabler | D19: Operations | E19: Basis | F19: Manual transport sequencing causes import errors. | G19: Inadvertent-Prudent | H19: n/a | I19: N | J19: n/a | K19: 3 | L19: 3 | M19: 8 | N19: 5 | O19: =IF(OR(N19="",N19=0),"",ROUND((K19+L19+M19)/N19,1)) -> 2.8 | P19: =IF(OR(O19="",X19="Done",X19="Rejected"),"",COUNTIFS($O$5:$O$204,">"&O19,$X$5:$X$204,"<>Done",$X$5:$X$204,"<>Rejected")+1) -> 14 | Q19: 12 | R19: 12 | S19: =IF(R19="","",R19*Settings!$B$5) -> 9000 | T19: =IF(Q19="","",Q19*12*Settings!$B$5/8) -> 13500 | U19: =IF(OR(S19="",T19="",T19=0),"",ROUND(S19/(T19/12),1)) -> 8 | V19: CIO office | W19: Basis lead | X19: New | Y19: Q2-2027 | Z19: 46286 | AB19: =IF(Z19="","",IF(AA19="",TODAY(),AA19)-Z19) -> 6 | AC19: =IF(AB19="","",IF(AND(OR(X19="New",X19="Triaged"),AB19>Settings!$B$9),"STALE",""))
A20: EX-016 | B20: Delivery note form prints wrong plant address | C20: Defect | D20: Process | E20: SD | F20: Cosmetic; workaround exists. | G20: Inadvertent-Prudent | H20: n/a | I20: N | J20: P4 | K20: 1 | L20: 1 | M20: 1 | N20: 1 | O20: =IF(OR(N20="",N20=0),"",ROUND((K20+L20+M20)/N20,1)) -> 3 | P20: =IF(OR(O20="",X20="Done",X20="Rejected"),"",COUNTIFS($O$5:$O$204,">"&O20,$X$5:$X$204,"<>Done",$X$5:$X$204,"<>Rejected")+1) -> 13 | Q20: 2 | R20: 1 | S20: =IF(R20="","",R20*Settings!$B$5) -> 750 | T20: =IF(Q20="","",Q20*12*Settings!$B$5/8) -> 2250 | U20: =IF(OR(S20="",T20="",T20=0),"",ROUND(S20/(T20/12),1)) -> 4 | V20: Shipping | W20: SD functional lead | X20: New | Y20: Backlog | Z20: 46183 | AB20: =IF(Z20="","",IF(AA20="",TODAY(),AA20)-Z20) -> 109 | AC20: =IF(AB20="","",IF(AND(OR(X20="New",X20="Triaged"),AB20>Settings!$B$9),"STALE","")) -> STALE
A21: EX-017 | B21: Z-field duplicates standard field (sales region on customer) | C21: Tech Debt | D21: Data | E21: SD | F21: Same value kept in two places; reports disagree. | G21: Inadvertent-Reckless | H21: C | I21: Y | J21: n/a | K21: 5 | L21: 3 | M21: 8 | N21: 3 | O21: =IF(OR(N21="",N21=0),"",ROUND((K21+L21+M21)/N21,1)) -> 5.3 | P21: =IF(OR(O21="",X21="Done",X21="Rejected"),"",COUNTIFS($O$5:$O$204,">"&O21,$X$5:$X$204,"<>Done",$X$5:$X$204,"<>Rejected")+1) -> 4 | Q21: 10 | R21: 8 | S21: =IF(R21="","",R21*Settings!$B$5) -> 6000 | T21: =IF(Q21="","",Q21*12*Settings!$B$5/8) -> 11250 | U21: =IF(OR(S21="",T21="",T21=0),"",ROUND(S21/(T21/12),1)) -> 6.4 | V21: Sales ops | W21: Data lead | X21: Ready | Y21: Q1-2027 | Z21: 46266 | AB21: =IF(Z21="","",IF(AA21="",TODAY(),AA21)-Z21) -> 26 | AC21: =IF(AB21="","",IF(AND(OR(X21="New",X21="Triaged"),AB21>Settings!$B$9),"STALE",""))
A22: EX-018 | B22: Automated regression tests for top 20 end-to-end processes | C22: Enabler | D22: Operations | E22: Cross-app | F22: Manual testing makes every change risky and slow. | G22: n/a | H22: n/a | I22: Y | J22: n/a | K22: 8 | L22: 5 | M22: 13 | N22: 13 | O22: =IF(OR(N22="",N22=0),"",ROUND((K22+L22+M22)/N22,1)) -> 2 | P22: =IF(OR(O22="",X22="Done",X22="Rejected"),"",COUNTIFS($O$5:$O$204,">"&O22,$X$5:$X$204,"<>Done",$X$5:$X$204,"<>Rejected")+1) -> 18 | Q22: 40 | R22: 50 | S22: =IF(R22="","",R22*Settings!$B$5) -> 37500 | T22: =IF(Q22="","",Q22*12*Settings!$B$5/8) -> 45000 | U22: =IF(OR(S22="",T22="",T22=0),"",ROUND(S22/(T22/12),1)) -> 10 | V22: CIO office | W22: QA lead | X22: New | Y22: Q2-2027 | Z22: 46286 | AB22: =IF(Z22="","",IF(AA22="",TODAY(),AA22)-Z22) -> 6 | AC22: =IF(AB22="","",IF(AND(OR(X22="New",X22="Triaged"),AB22>Settings!$B$9),"STALE","")) | AD22: Cloud ALM test management + automation tool
A23: EX-019 | B23: PI/PO interface inventory and migration wave plan | C23: Risk/Compliance | D23: Integration | E23: Integration | F23: Legacy middleware approaching end of mainstream maintenance. | G23: Deliberate-Prudent | H23: n/a | I23: Y | J23: n/a | K23: 5 | L23: 8 | M23: 13 | N23: 5 | O23: =IF(OR(N23="",N23=0),"",ROUND((K23+L23+M23)/N23,1)) -> 5.2 | P23: =IF(OR(O23="",X23="Done",X23="Rejected"),"",COUNTIFS($O$5:$O$204,">"&O23,$X$5:$X$204,"<>Done",$X$5:$X$204,"<>Rejected")+1) -> 5 | Q23: 0 | R23: 10 | S23: =IF(R23="","",R23*Settings!$B$5) -> 7500 | T23: =IF(Q23="","",Q23*12*Settings!$B$5/8) -> 0 | U23: =IF(OR(S23="",T23="",T23=0),"",ROUND(S23/(T23/12),1)) | V23: CIO office | W23: Integration lead | X23: Triaged | Y23: Q1-2027 | Z23: 46275 | AB23: =IF(Z23="","",IF(AA23="",TODAY(),AA23)-Z23) -> 17 | AC23: =IF(AB23="","",IF(AND(OR(X23="New",X23="Triaged"),AB23>Settings!$B$9),"STALE","")) | AD23: Only if PI/PO is in landscape - confirm
A24: EX-020 | B24: Joule / AI use-case readiness spike | C24: Feature | D24: Process | E24: Cross-app | F24: Business asking for AI features; need readiness view (licensing, clean core, data). | G24: n/a | H24: A | I24: N | J24: n/a | K24: 5 | L24: 2 | M24: 8 | N24: 2 | O24: =IF(OR(N24="",N24=0),"",ROUND((K24+L24+M24)/N24,1)) -> 7.5 | P24: =IF(OR(O24="",X24="Done",X24="Rejected"),"",COUNTIFS($O$5:$O$204,">"&O24,$X$5:$X$204,"<>Done",$X$5:$X$204,"<>Rejected")+1) -> 3 | Q24: 0 | R24: 5 | S24: =IF(R24="","",R24*Settings!$B$5) -> 3750 | T24: =IF(Q24="","",Q24*12*Settings!$B$5/8) -> 0 | U24: =IF(OR(S24="",T24="",T24=0),"",ROUND(S24/(T24/12),1)) | V24: CIO office | W24: Enterprise architect | X24: New | Y24: Q3-2027 | Z24: 46290 | AB24: =IF(Z24="","",IF(AA24="",TODAY(),AA24)-Z24) -> 2 | AC24: =IF(AB24="","",IF(AND(OR(X24="New",X24="Triaged"),AB24>Settings!$B$9),"STALE","")) | AD24: Timeboxed spike
O25: =IF(OR(N25="",N25=0),"",ROUND((K25+L25+M25)/N25,1)) | P25: =IF(OR(O25="",X25="Done",X25="Rejected"),"",COUNTIFS($O$5:$O$204,">"&O25,$X$5:$X$204,"<>Done",$X$5:$X$204,"<>Rejected")+1) | S25: =IF(R25="","",R25*Settings!$B$5) | T25: =IF(Q25="","",Q25*12*Settings!$B$5/8) | U25: =IF(OR(S25="",T25="",T25=0),"",ROUND(S25/(T25/12),1)) | AB25: =IF(Z25="","",IF(AA25="",TODAY(),AA25)-Z25) | AC25: =IF(AB25="","",IF(AND(OR(X25="New",X25="Triaged"),AB25>Settings!$B$9),"STALE",""))
O26: =IF(OR(N26="",N26=0),"",ROUND((K26+L26+M26)/N26,1)) | P26: =IF(OR(O26="",X26="Done",X26="Rejected"),"",COUNTIFS($O$5:$O$204,">"&O26,$X$5:$X$204,"<>Done",$X$5:$X$204,"<>Rejected")+1) | S26: =IF(R26="","",R26*Settings!$B$5) | T26: =IF(Q26="","",Q26*12*Settings!$B$5/8) | U26: =IF(OR(S26="",T26="",T26=0),"",ROUND(S26/(T26/12),1)) | AB26: =IF(Z26="","",IF(AA26="",TODAY(),AA26)-Z26) | AC26: =IF(AB26="","",IF(AND(OR(X26="New",X26="Triaged"),AB26>Settings!$B$9),"STALE",""))
O27: =IF(OR(N27="",N27=0),"",ROUND((K27+L27+M27)/N27,1)) | P27: =IF(OR(O27="",X27="Done",X27="Rejected"),"",COUNTIFS($O$5:$O$204,">"&O27,$X$5:$X$204,"<>Done",$X$5:$X$204,"<>Rejected")+1) | S27: =IF(R27="","",R27*Settings!$B$5) | T27: =IF(Q27="","",Q27*12*Settings!$B$5/8) | U27: =IF(OR(S27="",T27="",T27=0),"",ROUND(S27/(T27/12),1)) | AB27: =IF(Z27="","",IF(AA27="",TODAY(),AA27)-Z27) | AC27: =IF(AB27="","",IF(AND(OR(X27="New",X27="Triaged"),AB27>Settings!$B$9),"STALE",""))
O28: =IF(OR(N28="",N28=0),"",ROUND((K28+L28+M28)/N28,1)) | P28: =IF(OR(O28="",X28="Done",X28="Rejected"),"",COUNTIFS($O$5:$O$204,">"&O28,$X$5:$X$204,"<>Done",$X$5:$X$204,"<>Rejected")+1) | S28: =IF(R28="","",R28*Settings!$B$5) | T28: =IF(Q28="","",Q28*12*Settings!$B$5/8) | U28: =IF(OR(S28="",T28="",T28=0),"",ROUND(S28/(T28/12),1)) | AB28: =IF(Z28="","",IF(AA28="",TODAY(),AA28)-Z28) | AC28: =IF(AB28="","",IF(AND(OR(X28="New",X28="Triaged"),AB28>Settings!$B$9),"STALE",""))
O29: =IF(OR(N29="",N29=0),"",ROUND((K29+L29+M29)/N29,1)) | P29: =IF(OR(O29="",X29="Done",X29="Rejected"),"",COUNTIFS($O$5:$O$204,">"&O29,$X$5:$X$204,"<>Done",$X$5:$X$204,"<>Rejected")+1) | S29: =IF(R29="","",R29*Settings!$B$5) | T29: =IF(Q29="","",Q29*12*Settings!$B$5/8) | U29: =IF(OR(S29="",T29="",T29=0),"",ROUND(S29/(T29/12),1)) | AB29: =IF(Z29="","",IF(AA29="",TODAY(),AA29)-Z29) | AC29: =IF(AB29="","",IF(AND(OR(X29="New",X29="Triaged"),AB29>Settings!$B$9),"STALE",""))
O30: =IF(OR(N30="",N30=0),"",ROUND((K30+L30+M30)/N30,1)) | P30: =IF(OR(O30="",X30="Done",X30="Rejected"),"",COUNTIFS($O$5:$O$204,">"&O30,$X$5:$X$204,"<>Done",$X$5:$X$204,"<>Rejected")+1) | S30: =IF(R30="","",R30*Settings!$B$5) | T30: =IF(Q30="","",Q30*12*Settings!$B$5/8) | U30: =IF(OR(S30="",T30="",T30=0),"",ROUND(S30/(T30/12),1)) | AB30: =IF(Z30="","",IF(AA30="",TODAY(),AA30)-Z30) | AC30: =IF(AB30="","",IF(AND(OR(X30="New",X30="Triaged"),AB30>Settings!$B$9),"STALE",""))
O31: =IF(OR(N31="",N31=0),"",ROUND((K31+L31+M31)/N31,1)) | P31: =IF(OR(O31="",X31="Done",X31="Rejected"),"",COUNTIFS($O$5:$O$204,">"&O31,$X$5:$X$204,"<>Done",$X$5:$X$204,"<>Rejected")+1) | S31: =IF(R31="","",R31*Settings!$B$5) | T31: =IF(Q31="","",Q31*12*Settings!$B$5/8) | U31: =IF(OR(S31="",T31="",T31=0),"",ROUND(S31/(T31/12),1)) | AB31: =IF(Z31="","",IF(AA31="",TODAY(),AA31)-Z31) | AC31: =IF(AB31="","",IF(AND(OR(X31="New",X31="Triaged"),AB31>Settings!$B$9),"STALE",""))
O32: =IF(OR(N32="",N32=0),"",ROUND((K32+L32+M32)/N32,1)) | P32: =IF(OR(O32="",X32="Done",X32="Rejected"),"",COUNTIFS($O$5:$O$204,">"&O32,$X$5:$X$204,"<>Done",$X$5:$X$204,"<>Rejected")+1) | S32: =IF(R32="","",R32*Settings!$B$5) | T32: =IF(Q32="","",Q32*12*Settings!$B$5/8) | U32: =IF(OR(S32="",T32="",T32=0),"",ROUND(S32/(T32/12),1)) | AB32: =IF(Z32="","",IF(AA32="",TODAY(),AA32)-Z32) | AC32: =IF(AB32="","",IF(AND(OR(X32="New",X32="Triaged"),AB32>Settings!$B$9),"STALE",""))
O33: =IF(OR(N33="",N33=0),"",ROUND((K33+L33+M33)/N33,1)) | P33: =IF(OR(O33="",X33="Done",X33="Rejected"),"",COUNTIFS($O$5:$O$204,">"&O33,$X$5:$X$204,"<>Done",$X$5:$X$204,"<>Rejected")+1) | S33: =IF(R33="","",R33*Settings!$B$5) | T33: =IF(Q33="","",Q33*12*Settings!$B$5/8) | U33: =IF(OR(S33="",T33="",T33=0),"",ROUND(S33/(T33/12),1)) | AB33: =IF(Z33="","",IF(AA33="",TODAY(),AA33)-Z33) | AC33: =IF(AB33="","",IF(AND(OR(X33="New",X33="Triaged"),AB33>Settings!$B$9),"STALE",""))
O34: =IF(OR(N34="",N34=0),"",ROUND((K34+L34+M34)/N34,1)) | P34: =IF(OR(O34="",X34="Done",X34="Rejected"),"",COUNTIFS($O$5:$O$204,">"&O34,$X$5:$X$204,"<>Done",$X$5:$X$204,"<>Rejected")+1) | S34: =IF(R34="","",R34*Settings!$B$5) | T34: =IF(Q34="","",Q34*12*Settings!$B$5/8) | U34: =IF(OR(S34="",T34="",T34=0),"",ROUND(S34/(T34/12),1)) | AB34: =IF(Z34="","",IF(AA34="",TODAY(),AA34)-Z34) | AC34: =IF(AB34="","",IF(AND(OR(X34="New",X34="Triaged"),AB34>Settings!$B$9),"STALE",""))
O35: =IF(OR(N35="",N35=0),"",ROUND((K35+L35+M35)/N35,1)) | P35: =IF(OR(O35="",X35="Done",X35="Rejected"),"",COUNTIFS($O$5:$O$204,">"&O35,$X$5:$X$204,"<>Done",$X$5:$X$204,"<>Rejected")+1) | S35: =IF(R35="","",R35*Settings!$B$5) | T35: =IF(Q35="","",Q35*12*Settings!$B$5/8) | U35: =IF(OR(S35="",T35="",T35=0),"",ROUND(S35/(T35/12),1)) | AB35: =IF(Z35="","",IF(AA35="",TODAY(),AA35)-Z35) | AC35: =IF(AB35="","",IF(AND(OR(X35="New",X35="Triaged"),AB35>Settings!$B$9),"STALE",""))
O36: =IF(OR(N36="",N36=0),"",ROUND((K36+L36+M36)/N36,1)) | P36: =IF(OR(O36="",X36="Done",X36="Rejected"),"",COUNTIFS($O$5:$O$204,">"&O36,$X$5:$X$204,"<>Done",$X$5:$X$204,"<>Rejected")+1) | S36: =IF(R36="","",R36*Settings!$B$5) | T36: =IF(Q36="","",Q36*12*Settings!$B$5/8) | U36: =IF(OR(S36="",T36="",T36=0),"",ROUND(S36/(T36/12),1)) | AB36: =IF(Z36="","",IF(AA36="",TODAY(),AA36)-Z36) | AC36: =IF(AB36="","",IF(AND(OR(X36="New",X36="Triaged"),AB36>Settings!$B$9),"STALE",""))
... O204: =IF(OR(N204="",N204=0),"",ROUND((K204+L204+M204)/N204,1)) | P204: =IF(OR(O204="",X204="Done",X204="Rejected"),"",COUNTIFS($O$5:$O$204,">"&O204,$X$5:$X$204,"<>Done",$X$5:$X$204,"<>Rejected")+1) | S204: =IF(R204="","",R204*Settings!$B$5) | T204: =IF(Q204="","",Q204*12*Settings!$B$5/8) | U204: =IF(OR(S204="",T204="",T204=0),"",ROUND(S204/(T204/12),1)) | AB204: =IF(Z204="","",IF(AA204="",TODAY(),AA204)-Z204) | AC204: =IF(AB204="","",IF(AND(OR(X204="New",X204="Triaged"),AB204>Settings!$B$9),"STALE",""))

Sheet Capacity & Budget
A1: Capacity Allocation & Budget Guardrails
A2: Fund a stable team, then split its capacity by work type. Yellow = inputs. Demand is pulled live from the register (Principal person-days, open items).
A4: 1. Capacity by quarter
A5: Quarter | B5: Team FTE | C5: Working days | D5: Availability % | E5: Capacity (person-days) | F5: Budget cap (USD) | G5: Capacity cost (USD) | H5: Within budget? | J5: Note
A6: Q4-2026 | B6: 8 | C6: =Settings!$B$6 -> 60 | D6: =Settings!$B$7 -> 0.7 | E6: =ROUND(B6*C6*D6,0) -> 336 | F6: 380000 | G6: =B6*C6*Settings!$B$5 -> 360000 | H6: =IF(G6<=F6,"Yes","OVER by "&TEXT(G6-F6,"$#,##0")) -> Yes | J6: FTE and budget caps are placeholders. Capacity cost = FTE x working days x day rate (Settings).
A7: Q1-2027 | B7: 8 | C7: =Settings!$B$6 -> 60 | D7: =Settings!$B$7 -> 0.7 | E7: =ROUND(B7*C7*D7,0) -> 336 | F7: 380000 | G7: =B7*C7*Settings!$B$5 -> 360000 | H7: =IF(G7<=F7,"Yes","OVER by "&TEXT(G7-F7,"$#,##0")) -> Yes
A8: Q2-2027 | B8: 9 | C8: =Settings!$B$6 -> 60 | D8: =Settings!$B$7 -> 0.7 | E8: =ROUND(B8*C8*D8,0) -> 378 | F8: 420000 | G8: =B8*C8*Settings!$B$5 -> 405000 | H8: =IF(G8<=F8,"Yes","OVER by "&TEXT(G8-F8,"$#,##0")) -> Yes
A9: Q3-2027 | B9: 9 | C9: =Settings!$B$6 -> 60 | D9: =Settings!$B$7 -> 0.7 | E9: =ROUND(B9*C9*D9,0) -> 378 | F9: 420000 | G9: =B9*C9*Settings!$B$5 -> 405000 | H9: =IF(G9<=F9,"Yes","OVER by "&TEXT(G9-F9,"$#,##0")) -> Yes
A10: Q4-2027 | B10: 9 | C10: =Settings!$B$6 -> 60 | D10: =Settings!$B$7 -> 0.7 | E10: =ROUND(B10*C10*D10,0) -> 378 | F10: 420000 | G10: =B10*C10*Settings!$B$5 -> 405000 | H10: =IF(G10<=F10,"Yes","OVER by "&TEXT(G10-F10,"$#,##0")) -> Yes
A13: 2. Allocation guardrails (% of capacity by work type) - must total 100%
A14: Quarter | B14: Feature | C14: Defect | D14: Tech Debt | E14: Enabler | F14: Risk/Compliance | G14: Total | H14: Check
A15: Q4-2026 | B15: 0.3 | C15: 0.2 | D15: 0.25 | E15: 0.2 | F15: 0.05 | G15: =SUM(B15:F15) -> 1 | H15: =IF(ROUND(G15,4)=1,"OK","Must = 100%") -> OK
A16: Q1-2027 | B16: 0.35 | C16: 0.15 | D16: 0.25 | E16: 0.2 | F16: 0.05 | G16: =SUM(B16:F16) -> 1 | H16: =IF(ROUND(G16,4)=1,"OK","Must = 100%") -> OK
A17: Q2-2027 | B17: 0.4 | C17: 0.15 | D17: 0.25 | E17: 0.15 | F17: 0.05 | G17: =SUM(B17:F17) -> 1 | H17: =IF(ROUND(G17,4)=1,"OK","Must = 100%") -> OK
A18: Q3-2027 | B18: 0.45 | C18: 0.15 | D18: 0.2 | E18: 0.15 | F18: 0.05 | G18: =SUM(B18:F18) -> 1 | H18: =IF(ROUND(G18,4)=1,"OK","Must = 100%") -> OK
A19: Q4-2027 | B19: 0.5 | C19: 0.15 | D19: 0.2 | E19: 0.1 | F19: 0.05 | G19: =SUM(B19:F19) -> 1 | H19: =IF(ROUND(G19,4)=1,"OK","Must = 100%") -> OK
A22: 3. Planned capacity (person-days) vs open demand from register
A23: Quarter | B23: Feature - capacity | C23: Feature - demand | D23: Defect - capacity | E23: Defect - demand | F23: Tech Debt - capacity | G23: Tech Debt - demand | H23: Enabler - capacity | I23: Enabler - demand | J23: Risk/Compliance - capacity | K23: Risk/Compliance - demand | L23: Total capacity | M23: Total demand | N23: Gap (+ = spare)
A24: Q4-2026 | B24: =ROUND($E6*B15,0) -> 101 | C24: =SUMIFS('Tech Debt Register'!$R$5:$R$204,'Tech Debt Register'!$Y$5:$Y$204,$A24,'Tech Debt Register'!$C$5:$C$204,"Feature",'Tech Debt Register'!$X$5:$X$204,"<>Done",'Tech Debt Register'!$X$5:$X$204,"<>Rejected") -> 15 | D24: =ROUND($E6*C15,0) -> 67 | E24: =SUMIFS('Tech Debt Register'!$R$5:$R$204,'Tech Debt Register'!$Y$5:$Y$204,$A24,'Tech Debt Register'!$C$5:$C$204,"Defect",'Tech Debt Register'!$X$5:$X$204,"<>Done",'Tech Debt Register'!$X$5:$X$204,"<>Rejected") -> 7 | F24: =ROUND($E6*D15,0) -> 84 | G24: =SUMIFS('Tech Debt Register'!$R$5:$R$204,'Tech Debt Register'!$Y$5:$Y$204,$A24,'Tech Debt Register'!$C$5:$C$204,"Tech Debt",'Tech Debt Register'!$X$5:$X$204,"<>Done",'Tech Debt Register'!$X$5:$X$204,"<>Rejected") -> 0 | H24: =ROUND($E6*E15,0) -> 67 | I24: =SUMIFS('Tech Debt Register'!$R$5:$R$204,'Tech Debt Register'!$Y$5:$Y$204,$A24,'Tech Debt Register'!$C$5:$C$204,"Enabler",'Tech Debt Register'!$X$5:$X$204,"<>Done",'Tech Debt Register'!$X$5:$X$204,"<>Rejected") -> 35 | J24: =ROUND($E6*F15,0) -> 17 | K24: =SUMIFS('Tech Debt Register'!$R$5:$R$204,'Tech Debt Register'!$Y$5:$Y$204,$A24,'Tech Debt Register'!$C$5:$C$204,"Risk/Compliance",'Tech Debt Register'!$X$5:$X$204,"<>Done",'Tech Debt Register'!$X$5:$X$204,"<>Rejected") -> 0 | L24: =SUM(B24,D24,F24,H24,J24) -> 336 | M24: =SUM(C24,E24,G24,I24,K24) -> 57 | N24: =L24-M24 -> 279
A25: Q1-2027 | B25: =ROUND($E7*B16,0) -> 118 | C25: =SUMIFS('Tech Debt Register'!$R$5:$R$204,'Tech Debt Register'!$Y$5:$Y$204,$A25,'Tech Debt Register'!$C$5:$C$204,"Feature",'Tech Debt Register'!$X$5:$X$204,"<>Done",'Tech Debt Register'!$X$5:$X$204,"<>Rejected") -> 15 | D25: =ROUND($E7*C16,0) -> 50 | E25: =SUMIFS('Tech Debt Register'!$R$5:$R$204,'Tech Debt Register'!$Y$5:$Y$204,$A25,'Tech Debt Register'!$C$5:$C$204,"Defect",'Tech Debt Register'!$X$5:$X$204,"<>Done",'Tech Debt Register'!$X$5:$X$204,"<>Rejected") -> 0 | F25: =ROUND($E7*D16,0) -> 84 | G25: =SUMIFS('Tech Debt Register'!$R$5:$R$204,'Tech Debt Register'!$Y$5:$Y$204,$A25,'Tech Debt Register'!$C$5:$C$204,"Tech Debt",'Tech Debt Register'!$X$5:$X$204,"<>Done",'Tech Debt Register'!$X$5:$X$204,"<>Rejected") -> 68 | H25: =ROUND($E7*E16,0) -> 67 | I25: =SUMIFS('Tech Debt Register'!$R$5:$R$204,'Tech Debt Register'!$Y$5:$Y$204,$A25,'Tech Debt Register'!$C$5:$C$204,"Enabler",'Tech Debt Register'!$X$5:$X$204,"<>Done",'Tech Debt Register'!$X$5:$X$204,"<>Rejected") -> 0 | J25: =ROUND($E7*F16,0) -> 17 | K25: =SUMIFS('Tech Debt Register'!$R$5:$R$204,'Tech Debt Register'!$Y$5:$Y$204,$A25,'Tech Debt Register'!$C$5:$C$204,"Risk/Compliance",'Tech Debt Register'!$X$5:$X$204,"<>Done",'Tech Debt Register'!$X$5:$X$204,"<>Rejected") -> 10 | L25: =SUM(B25,D25,F25,H25,J25) -> 336 | M25: =SUM(C25,E25,G25,I25,K25) -> 93 | N25: =L25-M25 -> 243
A26: Q2-2027 | B26: =ROUND($E8*B17,0) -> 151 | C26: =SUMIFS('Tech Debt Register'!$R$5:$R$204,'Tech Debt Register'!$Y$5:$Y$204,$A26,'Tech Debt Register'!$C$5:$C$204,"Feature",'Tech Debt Register'!$X$5:$X$204,"<>Done",'Tech Debt Register'!$X$5:$X$204,"<>Rejected") -> 15 | D26: =ROUND($E8*C17,0) -> 57 | E26: =SUMIFS('Tech Debt Register'!$R$5:$R$204,'Tech Debt Register'!$Y$5:$Y$204,$A26,'Tech Debt Register'!$C$5:$C$204,"Defect",'Tech Debt Register'!$X$5:$X$204,"<>Done",'Tech Debt Register'!$X$5:$X$204,"<>Rejected") -> 0 | F26: =ROUND($E8*D17,0) -> 95 | G26: =SUMIFS('Tech Debt Register'!$R$5:$R$204,'Tech Debt Register'!$Y$5:$Y$204,$A26,'Tech Debt Register'!$C$5:$C$204,"Tech Debt",'Tech Debt Register'!$X$5:$X$204,"<>Done",'Tech Debt Register'!$X$5:$X$204,"<>Rejected") -> 90 | H26: =ROUND($E8*E17,0) -> 57 | I26: =SUMIFS('Tech Debt Register'!$R$5:$R$204,'Tech Debt Register'!$Y$5:$Y$204,$A26,'Tech Debt Register'!$C$5:$C$204,"Enabler",'Tech Debt Register'!$X$5:$X$204,"<>Done",'Tech Debt Register'!$X$5:$X$204,"<>Rejected") -> 62 | J26: =ROUND($E8*F17,0) -> 19 | K26: =SUMIFS('Tech Debt Register'!$R$5:$R$204,'Tech Debt Register'!$Y$5:$Y$204,$A26,'Tech Debt Register'!$C$5:$C$204,"Risk/Compliance",'Tech Debt Register'!$X$5:$X$204,"<>Done",'Tech Debt Register'!$X$5:$X$204,"<>Rejected") -> 45 | L26: =SUM(B26,D26,F26,H26,J26) -> 379 | M26: =SUM(C26,E26,G26,I26,K26) -> 212 | N26: =L26-M26 -> 167
A27: Q3-2027 | B27: =ROUND($E9*B18,0) -> 170 | C27: =SUMIFS('Tech Debt Register'!$R$5:$R$204,'Tech Debt Register'!$Y$5:$Y$204,$A27,'Tech Debt Register'!$C$5:$C$204,"Feature",'Tech Debt Register'!$X$5:$X$204,"<>Done",'Tech Debt Register'!$X$5:$X$204,"<>Rejected") -> 5 | D27: =ROUND($E9*C18,0) -> 57 | E27: =SUMIFS('Tech Debt Register'!$R$5:$R$204,'Tech Debt Register'!$Y$5:$Y$204,$A27,'Tech Debt Register'!$C$5:$C$204,"Defect",'Tech Debt Register'!$X$5:$X$204,"<>Done",'Tech Debt Register'!$X$5:$X$204,"<>Rejected") -> 0 | F27: =ROUND($E9*D18,0) -> 76 | G27: =SUMIFS('Tech Debt Register'!$R$5:$R$204,'Tech Debt Register'!$Y$5:$Y$204,$A27,'Tech Debt Register'!$C$5:$C$204,"Tech Debt",'Tech Debt Register'!$X$5:$X$204,"<>Done",'Tech Debt Register'!$X$5:$X$204,"<>Rejected") -> 30 | H27: =ROUND($E9*E18,0) -> 57 | I27: =SUMIFS('Tech Debt Register'!$R$5:$R$204,'Tech Debt Register'!$Y$5:$Y$204,$A27,'Tech Debt Register'!$C$5:$C$204,"Enabler",'Tech Debt Register'!$X$5:$X$204,"<>Done",'Tech Debt Register'!$X$5:$X$204,"<>Rejected") -> 0 | J27: =ROUND($E9*F18,0) -> 19 | K27: =SUMIFS('Tech Debt Register'!$R$5:$R$204,'Tech Debt Register'!$Y$5:$Y$204,$A27,'Tech Debt Register'!$C$5:$C$204,"Risk/Compliance",'Tech Debt Register'!$X$5:$X$204,"<>Done",'Tech Debt Register'!$X$5:$X$204,"<>Rejected") -> 0 | L27: =SUM(B27,D27,F27,H27,J27) -> 379 | M27: =SUM(C27,E27,G27,I27,K27) -> 35 | N27: =L27-M27 -> 344
A28: Q4-2027 | B28: =ROUND($E10*B19,0) -> 189 | C28: =SUMIFS('Tech Debt Register'!$R$5:$R$204,'Tech Debt Register'!$Y$5:$Y$204,$A28,'Tech Debt Register'!$C$5:$C$204,"Feature",'Tech Debt Register'!$X$5:$X$204,"<>Done",'Tech Debt Register'!$X$5:$X$204,"<>Rejected") -> 0 | D28: =ROUND($E10*C19,0) -> 57 | E28: =SUMIFS('Tech Debt Register'!$R$5:$R$204,'Tech Debt Register'!$Y$5:$Y$204,$A28,'Tech Debt Register'!$C$5:$C$204,"Defect",'Tech Debt Register'!$X$5:$X$204,"<>Done",'Tech Debt Register'!$X$5:$X$204,"<>Rejected") -> 0 | F28: =ROUND($E10*D19,0) -> 76 | G28: =SUMIFS('Tech Debt Register'!$R$5:$R$204,'Tech Debt Register'!$Y$5:$Y$204,$A28,'Tech Debt Register'!$C$5:$C$204,"Tech Debt",'Tech Debt Register'!$X$5:$X$204,"<>Done",'Tech Debt Register'!$X$5:$X$204,"<>Rejected") -> 0 | H28: =ROUND($E10*E19,0) -> 38 | I28: =SUMIFS('Tech Debt Register'!$R$5:$R$204,'Tech Debt Register'!$Y$5:$Y$204,$A28,'Tech Debt Register'!$C$5:$C$204,"Enabler",'Tech Debt Register'!$X$5:$X$204,"<>Done",'Tech Debt Register'!$X$5:$X$204,"<>Rejected") -> 0 | J28: =ROUND($E10*F19,0) -> 19 | K28: =SUMIFS('Tech Debt Register'!$R$5:$R$204,'Tech Debt Register'!$Y$5:$Y$204,$A28,'Tech Debt Register'!$C$5:$C$204,"Risk/Compliance",'Tech Debt Register'!$X$5:$X$204,"<>Done",'Tech Debt Register'!$X$5:$X$204,"<>Rejected") -> 0 | L28: =SUM(B28,D28,F28,H28,J28) -> 379 | M28: =SUM(C28,E28,G28,I28,K28) -> 0 | N28: =L28-M28 -> 379
A30: Amber = demand for that work type exceeds its guardrail -> re-prioritise, move the quarter, or consciously flex the allocation at the monthly portfolio review.
A31: Rule of thumb: never let Tech Debt + Enabler drop below ~25% while clean-core KPIs are red; P1/P2 defects are funded from the Defect bucket first.

Sheet Roadmap
A1: 15-Month Roadmap (Oct 2026 - Dec 2027)
A2: Enter start / end dates; bars draw automatically. Dates are proposals for discussion.
A4: Workstream | B4: Activity | C4: Owner | D4: Start | E4: End | F4: Oct-26 | G4: Nov-26 | H4: Dec-26 | I4: Jan-27 | J4: Feb-27 | K4: Mar-27 | L4: Apr-27 | M4: May-27 | N4: Jun-27 | O4: Jul-27 | P4: Aug-27 | Q4: Sep-27 | R4: Oct-27 | S4: Nov-27 | T4: Dec-27
A5: Governance | B5: Stand up CCoE / design authority, backlog tool, cadences | C5: EA + CIO office | D5: 46300 | E5: 46339 | F5: =IF(AND($D5<=EOMONTH(DATE(2026,10,1),0),$E5>=DATE(2026,10,1)),1,"") -> 1 | G5: =IF(AND($D5<=EOMONTH(DATE(2026,11,1),0),$E5>=DATE(2026,11,1)),1,"") -> 1 | H5: =IF(AND($D5<=EOMONTH(DATE(2026,12,1),0),$E5>=DATE(2026,12,1)),1,"") | I5: =IF(AND($D5<=EOMONTH(DATE(2027,1,1),0),$E5>=DATE(2027,1,1)),1,"") | J5: =IF(AND($D5<=EOMONTH(DATE(2027,2,1),0),$E5>=DATE(2027,2,1)),1,"") | K5: =IF(AND($D5<=EOMONTH(DATE(2027,3,1),0),$E5>=DATE(2027,3,1)),1,"") | L5: =IF(AND($D5<=EOMONTH(DATE(2027,4,1),0),$E5>=DATE(2027,4,1)),1,"") | M5: =IF(AND($D5<=EOMONTH(DATE(2027,5,1),0),$E5>=DATE(2027,5,1)),1,"") | N5: =IF(AND($D5<=EOMONTH(DATE(2027,6,1),0),$E5>=DATE(2027,6,1)),1,"") | O5: =IF(AND($D5<=EOMONTH(DATE(2027,7,1),0),$E5>=DATE(2027,7,1)),1,"") | P5: =IF(AND($D5<=EOMONTH(DATE(2027,8,1),0),$E5>=DATE(2027,8,1)),1,"") | Q5: =IF(AND($D5<=EOMONTH(DATE(2027,9,1),0),$E5>=DATE(2027,9,1)),1,"") | R5: =IF(AND($D5<=EOMONTH(DATE(2027,10,1),0),$E5>=DATE(2027,10,1)),1,"") | S5: =IF(AND($D5<=EOMONTH(DATE(2027,11,1),0),$E5>=DATE(2027,11,1)),1,"") | T5: =IF(AND($D5<=EOMONTH(DATE(2027,12,1),0),$E5>=DATE(2027,12,1)),1,"")
A6: Governance | B6: Discovery & baseline (Readiness Check, Pathfinder, ATC, SCMON, interface + data inventory) | C6: EA | D6: 46300 | E6: 46374 | F6: =IF(AND($D6<=EOMONTH(DATE(2026,10,1),0),$E6>=DATE(2026,10,1)),1,"") -> 1 | G6: =IF(AND($D6<=EOMONTH(DATE(2026,11,1),0),$E6>=DATE(2026,11,1)),1,"") -> 1 | H6: =IF(AND($D6<=EOMONTH(DATE(2026,12,1),0),$E6>=DATE(2026,12,1)),1,"") -> 1 | I6: =IF(AND($D6<=EOMONTH(DATE(2027,1,1),0),$E6>=DATE(2027,1,1)),1,"") | J6: =IF(AND($D6<=EOMONTH(DATE(2027,2,1),0),$E6>=DATE(2027,2,1)),1,"") | K6: =IF(AND($D6<=EOMONTH(DATE(2027,3,1),0),$E6>=DATE(2027,3,1)),1,"") | L6: =IF(AND($D6<=EOMONTH(DATE(2027,4,1),0),$E6>=DATE(2027,4,1)),1,"") | M6: =IF(AND($D6<=EOMONTH(DATE(2027,5,1),0),$E6>=DATE(2027,5,1)),1,"") | N6: =IF(AND($D6<=EOMONTH(DATE(2027,6,1),0),$E6>=DATE(2027,6,1)),1,"") | O6: =IF(AND($D6<=EOMONTH(DATE(2027,7,1),0),$E6>=DATE(2027,7,1)),1,"") | P6: =IF(AND($D6<=EOMONTH(DATE(2027,8,1),0),$E6>=DATE(2027,8,1)),1,"") | Q6: =IF(AND($D6<=EOMONTH(DATE(2027,9,1),0),$E6>=DATE(2027,9,1)),1,"") | R6: =IF(AND($D6<=EOMONTH(DATE(2027,10,1),0),$E6>=DATE(2027,10,1)),1,"") | S6: =IF(AND($D6<=EOMONTH(DATE(2027,11,1),0),$E6>=DATE(2027,11,1)),1,"") | T6: =IF(AND($D6<=EOMONTH(DATE(2027,12,1),0),$E6>=DATE(2027,12,1)),1,"")
A7: Governance | B7: Monthly portfolio review + quarterly roadmap refresh | C7: CIO office | D7: 46327 | E7: 46752 | F7: =IF(AND($D7<=EOMONTH(DATE(2026,10,1),0),$E7>=DATE(2026,10,1)),1,"") | G7: =IF(AND($D7<=EOMONTH(DATE(2026,11,1),0),$E7>=DATE(2026,11,1)),1,"") -> 1 | H7: =IF(AND($D7<=EOMONTH(DATE(2026,12,1),0),$E7>=DATE(2026,12,1)),1,"") -> 1 | I7: =IF(AND($D7<=EOMONTH(DATE(2027,1,1),0),$E7>=DATE(2027,1,1)),1,"") -> 1 | J7: =IF(AND($D7<=EOMONTH(DATE(2027,2,1),0),$E7>=DATE(2027,2,1)),1,"") -> 1 | K7: =IF(AND($D7<=EOMONTH(DATE(2027,3,1),0),$E7>=DATE(2027,3,1)),1,"") -> 1 | L7: =IF(AND($D7<=EOMONTH(DATE(2027,4,1),0),$E7>=DATE(2027,4,1)),1,"") -> 1 | M7: =IF(AND($D7<=EOMONTH(DATE(2027,5,1),0),$E7>=DATE(2027,5,1)),1,"") -> 1 | N7: =IF(AND($D7<=EOMONTH(DATE(2027,6,1),0),$E7>=DATE(2027,6,1)),1,"") -> 1 | O7: =IF(AND($D7<=EOMONTH(DATE(2027,7,1),0),$E7>=DATE(2027,7,1)),1,"") -> 1 | P7: =IF(AND($D7<=EOMONTH(DATE(2027,8,1),0),$E7>=DATE(2027,8,1)),1,"") -> 1 | Q7: =IF(AND($D7<=EOMONTH(DATE(2027,9,1),0),$E7>=DATE(2027,9,1)),1,"") -> 1 | R7: =IF(AND($D7<=EOMONTH(DATE(2027,10,1),0),$E7>=DATE(2027,10,1)),1,"") -> 1 | S7: =IF(AND($D7<=EOMONTH(DATE(2027,11,1),0),$E7>=DATE(2027,11,1)),1,"") -> 1 | T7: =IF(AND($D7<=EOMONTH(DATE(2027,12,1),0),$E7>=DATE(2027,12,1)),1,"") -> 1
A8: UX / Fiori | B8: Fiori foundation: FLP, spaces & pages, roles, performance | C8: Basis / Fiori lead | D8: 46314 | E8: 46416 | F8: =IF(AND($D8<=EOMONTH(DATE(2026,10,1),0),$E8>=DATE(2026,10,1)),1,"") -> 1 | G8: =IF(AND($D8<=EOMONTH(DATE(2026,11,1),0),$E8>=DATE(2026,11,1)),1,"") -> 1 | H8: =IF(AND($D8<=EOMONTH(DATE(2026,12,1),0),$E8>=DATE(2026,12,1)),1,"") -> 1 | I8: =IF(AND($D8<=EOMONTH(DATE(2027,1,1),0),$E8>=DATE(2027,1,1)),1,"") -> 1 | J8: =IF(AND($D8<=EOMONTH(DATE(2027,2,1),0),$E8>=DATE(2027,2,1)),1,"") | K8: =IF(AND($D8<=EOMONTH(DATE(2027,3,1),0),$E8>=DATE(2027,3,1)),1,"") | L8: =IF(AND($D8<=EOMONTH(DATE(2027,4,1),0),$E8>=DATE(2027,4,1)),1,"") | M8: =IF(AND($D8<=EOMONTH(DATE(2027,5,1),0),$E8>=DATE(2027,5,1)),1,"") | N8: =IF(AND($D8<=EOMONTH(DATE(2027,6,1),0),$E8>=DATE(2027,6,1)),1,"") | O8: =IF(AND($D8<=EOMONTH(DATE(2027,7,1),0),$E8>=DATE(2027,7,1)),1,"") | P8: =IF(AND($D8<=EOMONTH(DATE(2027,8,1),0),$E8>=DATE(2027,8,1)),1,"") | Q8: =IF(AND($D8<=EOMONTH(DATE(2027,9,1),0),$E8>=DATE(2027,9,1)),1,"") | R8: =IF(AND($D8<=EOMONTH(DATE(2027,10,1),0),$E8>=DATE(2027,10,1)),1,"") | S8: =IF(AND($D8<=EOMONTH(DATE(2027,11,1),0),$E8>=DATE(2027,11,1)),1,"") | T8: =IF(AND($D8<=EOMONTH(DATE(2027,12,1),0),$E8>=DATE(2027,12,1)),1,"")
A9: UX / Fiori | B9: Wave 1 Fiori apps: Finance (AP/AR/GL) | C9: Finance + Fiori lead | D9: 46357 | E9: 46477 | F9: =IF(AND($D9<=EOMONTH(DATE(2026,10,1),0),$E9>=DATE(2026,10,1)),1,"") | G9: =IF(AND($D9<=EOMONTH(DATE(2026,11,1),0),$E9>=DATE(2026,11,1)),1,"") | H9: =IF(AND($D9<=EOMONTH(DATE(2026,12,1),0),$E9>=DATE(2026,12,1)),1,"") -> 1 | I9: =IF(AND($D9<=EOMONTH(DATE(2027,1,1),0),$E9>=DATE(2027,1,1)),1,"") -> 1 | J9: =IF(AND($D9<=EOMONTH(DATE(2027,2,1),0),$E9>=DATE(2027,2,1)),1,"") -> 1 | K9: =IF(AND($D9<=EOMONTH(DATE(2027,3,1),0),$E9>=DATE(2027,3,1)),1,"") -> 1 | L9: =IF(AND($D9<=EOMONTH(DATE(2027,4,1),0),$E9>=DATE(2027,4,1)),1,"") | M9: =IF(AND($D9<=EOMONTH(DATE(2027,5,1),0),$E9>=DATE(2027,5,1)),1,"") | N9: =IF(AND($D9<=EOMONTH(DATE(2027,6,1),0),$E9>=DATE(2027,6,1)),1,"") | O9: =IF(AND($D9<=EOMONTH(DATE(2027,7,1),0),$E9>=DATE(2027,7,1)),1,"") | P9: =IF(AND($D9<=EOMONTH(DATE(2027,8,1),0),$E9>=DATE(2027,8,1)),1,"") | Q9: =IF(AND($D9<=EOMONTH(DATE(2027,9,1),0),$E9>=DATE(2027,9,1)),1,"") | R9: =IF(AND($D9<=EOMONTH(DATE(2027,10,1),0),$E9>=DATE(2027,10,1)),1,"") | S9: =IF(AND($D9<=EOMONTH(DATE(2027,11,1),0),$E9>=DATE(2027,11,1)),1,"") | T9: =IF(AND($D9<=EOMONTH(DATE(2027,12,1),0),$E9>=DATE(2027,12,1)),1,"")
A10: UX / Fiori | B10: Wave 2 Fiori apps: Supply chain (MRP, inventory, purchasing) | C10: SCM + Fiori lead | D10: 46447 | E10: 46598 | F10: =IF(AND($D10<=EOMONTH(DATE(2026,10,1),0),$E10>=DATE(2026,10,1)),1,"") | G10: =IF(AND($D10<=EOMONTH(DATE(2026,11,1),0),$E10>=DATE(2026,11,1)),1,"") | H10: =IF(AND($D10<=EOMONTH(DATE(2026,12,1),0),$E10>=DATE(2026,12,1)),1,"") | I10: =IF(AND($D10<=EOMONTH(DATE(2027,1,1),0),$E10>=DATE(2027,1,1)),1,"") | J10: =IF(AND($D10<=EOMONTH(DATE(2027,2,1),0),$E10>=DATE(2027,2,1)),1,"") | K10: =IF(AND($D10<=EOMONTH(DATE(2027,3,1),0),$E10>=DATE(2027,3,1)),1,"") -> 1 | L10: =IF(AND($D10<=EOMONTH(DATE(2027,4,1),0),$E10>=DATE(2027,4,1)),1,"") -> 1 | M10: =IF(AND($D10<=EOMONTH(DATE(2027,5,1),0),$E10>=DATE(2027,5,1)),1,"") -> 1 | N10: =IF(AND($D10<=EOMONTH(DATE(2027,6,1),0),$E10>=DATE(2027,6,1)),1,"") -> 1 | O10: =IF(AND($D10<=EOMONTH(DATE(2027,7,1),0),$E10>=DATE(2027,7,1)),1,"") -> 1 | P10: =IF(AND($D10<=EOMONTH(DATE(2027,8,1),0),$E10>=DATE(2027,8,1)),1,"") | Q10: =IF(AND($D10<=EOMONTH(DATE(2027,9,1),0),$E10>=DATE(2027,9,1)),1,"") | R10: =IF(AND($D10<=EOMONTH(DATE(2027,10,1),0),$E10>=DATE(2027,10,1)),1,"") | S10: =IF(AND($D10<=EOMONTH(DATE(2027,11,1),0),$E10>=DATE(2027,11,1)),1,"") | T10: =IF(AND($D10<=EOMONTH(DATE(2027,12,1),0),$E10>=DATE(2027,12,1)),1,"")
A11: UX / Fiori | B11: Wave 3 Fiori apps: Sales, quality, maintenance | C11: Business leads | D11: 46569 | E11: 46721 | F11: =IF(AND($D11<=EOMONTH(DATE(2026,10,1),0),$E11>=DATE(2026,10,1)),1,"") | G11: =IF(AND($D11<=EOMONTH(DATE(2026,11,1),0),$E11>=DATE(2026,11,1)),1,"") | H11: =IF(AND($D11<=EOMONTH(DATE(2026,12,1),0),$E11>=DATE(2026,12,1)),1,"") | I11: =IF(AND($D11<=EOMONTH(DATE(2027,1,1),0),$E11>=DATE(2027,1,1)),1,"") | J11: =IF(AND($D11<=EOMONTH(DATE(2027,2,1),0),$E11>=DATE(2027,2,1)),1,"") | K11: =IF(AND($D11<=EOMONTH(DATE(2027,3,1),0),$E11>=DATE(2027,3,1)),1,"") | L11: =IF(AND($D11<=EOMONTH(DATE(2027,4,1),0),$E11>=DATE(2027,4,1)),1,"") | M11: =IF(AND($D11<=EOMONTH(DATE(2027,5,1),0),$E11>=DATE(2027,5,1)),1,"") | N11: =IF(AND($D11<=EOMONTH(DATE(2027,6,1),0),$E11>=DATE(2027,6,1)),1,"") | O11: =IF(AND($D11<=EOMONTH(DATE(2027,7,1),0),$E11>=DATE(2027,7,1)),1,"") -> 1 | P11: =IF(AND($D11<=EOMONTH(DATE(2027,8,1),0),$E11>=DATE(2027,8,1)),1,"") -> 1 | Q11: =IF(AND($D11<=EOMONTH(DATE(2027,9,1),0),$E11>=DATE(2027,9,1)),1,"") -> 1 | R11: =IF(AND($D11<=EOMONTH(DATE(2027,10,1),0),$E11>=DATE(2027,10,1)),1,"") -> 1 | S11: =IF(AND($D11<=EOMONTH(DATE(2027,11,1),0),$E11>=DATE(2027,11,1)),1,"") -> 1 | T11: =IF(AND($D11<=EOMONTH(DATE(2027,12,1),0),$E11>=DATE(2027,12,1)),1,"")
A12: Work Zone | B12: Work Zone standard: subaccount, IdP, content federation | C12: BTP lead | D12: 46328 | E12: 46416 | F12: =IF(AND($D12<=EOMONTH(DATE(2026,10,1),0),$E12>=DATE(2026,10,1)),1,"") | G12: =IF(AND($D12<=EOMONTH(DATE(2026,11,1),0),$E12>=DATE(2026,11,1)),1,"") -> 1 | H12: =IF(AND($D12<=EOMONTH(DATE(2026,12,1),0),$E12>=DATE(2026,12,1)),1,"") -> 1 | I12: =IF(AND($D12<=EOMONTH(DATE(2027,1,1),0),$E12>=DATE(2027,1,1)),1,"") -> 1 | J12: =IF(AND($D12<=EOMONTH(DATE(2027,2,1),0),$E12>=DATE(2027,2,1)),1,"") | K12: =IF(AND($D12<=EOMONTH(DATE(2027,3,1),0),$E12>=DATE(2027,3,1)),1,"") | L12: =IF(AND($D12<=EOMONTH(DATE(2027,4,1),0),$E12>=DATE(2027,4,1)),1,"") | M12: =IF(AND($D12<=EOMONTH(DATE(2027,5,1),0),$E12>=DATE(2027,5,1)),1,"") | N12: =IF(AND($D12<=EOMONTH(DATE(2027,6,1),0),$E12>=DATE(2027,6,1)),1,"") | O12: =IF(AND($D12<=EOMONTH(DATE(2027,7,1),0),$E12>=DATE(2027,7,1)),1,"") | P12: =IF(AND($D12<=EOMONTH(DATE(2027,8,1),0),$E12>=DATE(2027,8,1)),1,"") | Q12: =IF(AND($D12<=EOMONTH(DATE(2027,9,1),0),$E12>=DATE(2027,9,1)),1,"") | R12: =IF(AND($D12<=EOMONTH(DATE(2027,10,1),0),$E12>=DATE(2027,10,1)),1,"") | S12: =IF(AND($D12<=EOMONTH(DATE(2027,11,1),0),$E12>=DATE(2027,11,1)),1,"") | T12: =IF(AND($D12<=EOMONTH(DATE(2027,12,1),0),$E12>=DATE(2027,12,1)),1,"")
