Workbook

Sheet Schedule
A1: Project NorthStar - SAP S/4HANA 2023 SPS06 upgrade schedule
A2: ="As of "&TEXT(AsOf,"ddd d mmm yyyy")&" | Update the Status column daily (drop-down). Phase rows roll up by themselves. | CONFIDENTIAL AND PROPRIETARY TO INTERNATIONAL" -> As of Sun 18 Oct 2026 | Update the Status column daily (drop-down). Phase rows roll up by themselves. | CONFIDENTIAL AND PROPRIETARY TO INTERNATIONAL
L3: 46307 | S3: 46314 | Z3: 46321 | AG3: 46328 | AN3: 46335 | AU3: 46342 | BB3: 46349 | BI3: 46356 | BP3: 46363 | BW3: 46370 | CD3: 46377 | CK3: 46384
A4: ID | B4: Task | C4: Team | D4: Days | E4: Start | F4: Finish | G4: Status | H4: % Complete | I4: Predecessors | J4: Detail tasks | K4: Type | L4: 46307 | M4: 46308 | N4: 46309 | O4: 46310 | P4: 46311 | Q4: 46312 | R4: 46313 | S4: 46314 | T4: 46315 | U4: 46316 | V4: 46317 | W4: 46318 | X4: 46319 | Y4: 46320 | Z4: 46321 | AA4: 46322 | AB4: 46323 | AC4: 46324 | AD4: 46325 | AE4: 46326 | AF4: 46327 | AG4: 46328 | AH4: 46329 | AI4: 46330 | AJ4: 46331 | AK4: 46332 | AL4: 46333 | AM4: 46334 | AN4: 46335 | AO4: 46336 | AP4: 46337 | AQ4: 46338 | AR4: 46339 | AS4: 46340 | AT4: 46341 | AU4: 46342 | AV4: 46343 | AW4: 46344 | AX4: 46345 | AY4: 46346 | AZ4: 46347 | BA4: 46348 | BB4: 46349 | BC4: 46350 | BD4: 46351 | BE4: 46352 | BF4: 46353 | BG4: 46354 | BH4: 46355 | BI4: 46356 | BJ4: 46357 | BK4: 46358 | BL4: 46359 | BM4: 46360 | BN4: 46361 | BO4: 46362 | BP4: 46363 | BQ4: 46364 | BR4: 46365 | BS4: 46366 | BT4: 46367 | BU4: 46368 | BV4: 46369 | BW4: 46370 | BX4: 46371 | BY4: 46372 | BZ4: 46373 | CA4: 46374 | CB4: 46375 | CC4: 46376 | CD4: 46377 | CE4: 46378 | CF4: 46379 | CG4: 46380 | CH4: 46381 | CI4: 46382 | CJ4: 46383 | CK4: 46384 | CL4: 46385 | CM4: 46386 | CN4: 46387 | CO4: 46388 | CP4: 46389 | CQ4: 46390
A5: 0 | B5: Start-up | D5: =IF(OR(E5="",F5=""),"",F5-E5+1) -> 14 | E5: =MIN(E6:E9) -> 46297 | F5: =MAX(F6:F9) -> 46310 | G5: =IF(COUNTIF(G6:G9,"Blocked")>0,"Blocked",IF(COUNTIF(G6:G9,"At Risk")>0,"At Risk",IF(COUNTIF(G6:G9,"Complete")=ROWS(G6:G9),"Complete",IF(COUNTIF(G6:G9,"Not Started")=ROWS(G6:G9),"Not Started","On Track")))) -> Complete | H5: =IFERROR(SUMPRODUCT(D6:D9,H6:H9)/SUM(D6:D9),0) -> 1 | K5: Summary
A6: 0.1 | B6: Triage SAP side-effect notes | C6: PwC Tech | D6: =IF(K6="Milestone",0,F6-E6+1) -> 5 | E6: 46297 | F6: 46301 | G6: Complete | H6: =IF(G6="Complete",1,IF(OR(G6="Not Started",K6="Milestone",AsOf<E6),0,MIN(0.9,MAX(0,(AsOf-E6+1)/(F6-E6+1))))) -> 1 | J6: H.4 | K6: Task
A7: 0.2 | B7: Plan XS4 stack and request update | C7: INTL Basis | D7: =IF(K7="Milestone",0,F7-E7+1) -> 2 | E7: 46298 | F7: 46299 | G7: Complete | H7: =IF(G7="Complete",1,IF(OR(G7="Not Started",K7="Milestone",AsOf<E7),0,MIN(0.9,MAX(0,(AsOf-E7+1)/(F7-E7+1))))) -> 1 | J7: H.1, H.2 | K7: Task
A8: 0.3 | B8: Close first XS4 update run (SUM reset) | C8: SAP ECS | D8: =IF(K8="Milestone",0,F8-E8+1) -> 8 | E8: 46302 | F8: 46309 | G8: Complete | H8: =IF(G8="Complete",1,IF(OR(G8="Not Started",K8="Milestone",AsOf<E8),0,MIN(0.9,MAX(0,(AsOf-E8+1)/(F8-E8+1))))) -> 1 | I8: 0.2 | J8: H.3 | K8: Task
A9: 0.4 | B9: ◆ Approach set: Sandbox = copy of DS4 | C9: INTL Basis | D9: =IF(K9="Milestone",0,F9-E9+1) -> 0 | E9: 46310 | F9: 46310 | G9: Complete | H9: =IF(G9="Complete",1,IF(OR(G9="Not Started",K9="Milestone",AsOf<E9),0,MIN(0.9,MAX(0,(AsOf-E9+1)/(F9-E9+1))))) -> 1 | I9: 0.3 | J9: H.5 | K9: Milestone | L9: =IF(L$4=$E9,"◆","") | M9: =IF(M$4=$E9,"◆","") | N9: =IF(N$4=$E9,"◆","") | O9: =IF(O$4=$E9,"◆","") -> ◆ | P9: =IF(P$4=$E9,"◆","") | Q9: =IF(Q$4=$E9,"◆","") | R9: =IF(R$4=$E9,"◆","") | S9: =IF(S$4=$E9,"◆","") | ... CQ9: =IF(CQ$4=$E9,"◆","")
A10: 1 | B10: Prepare Sandbox | D10: =IF(OR(E10="",F10=""),"",F10-E10+1) -> 14 | E10: =MIN(E11:E29) -> 46310 | F10: =MAX(F11:F29) -> 46323 | G10: =IF(COUNTIF(G11:G29,"Blocked")>0,"Blocked",IF(COUNTIF(G11:G29,"At Risk")>0,"At Risk",IF(COUNTIF(G11:G29,"Complete")=ROWS(G11:G29),"Complete",IF(COUNTIF(G11:G29,"Not Started")=ROWS(G11:G29),"Not Started","On Track")))) -> On Track | H10: =IFERROR(SUMPRODUCT(D11:D29,H11:H29)/SUM(D11:D29),0) -> 0.17283951 | K10: Summary
A11: 1.1 | B11: Align plan with PwC Tech | C11: PwC Tech | D11: =IF(K11="Milestone",0,F11-E11+1) -> 2 | E11: 46310 | F11: 46311 | G11: Complete | H11: =IF(G11="Complete",1,IF(OR(G11="Not Started",K11="Milestone",AsOf<E11),0,MIN(0.9,MAX(0,(AsOf-E11+1)/(F11-E11+1))))) -> 1 | I11: 0.4 | J11: 0.01a | K11: Task
A12: 1.2 | B12: Review plan (functional streams) | C12: PwC Functional | D12: =IF(K12="Milestone",0,F12-E12+1) -> 4 | E12: 46311 | F12: 46314 | G12: On Track | H12: =IF(G12="Complete",1,IF(OR(G12="Not Started",K12="Milestone",AsOf<E12),0,MIN(0.9,MAX(0,(AsOf-E12+1)/(F12-E12+1))))) -> 0.75 | I12: 1.1 | J12: 0.01b | K12: Task
A13: 1.3 | B13: Implement SAP Notes in DS4 | C13: INTL Basis | D13: =IF(K13="Milestone",0,F13-E13+1) -> 2 | E13: 46310 | F13: 46311 | G13: Complete | H13: =IF(G13="Complete",1,IF(OR(G13="Not Started",K13="Milestone",AsOf<E13),0,MIN(0.9,MAX(0,(AsOf-E13+1)/(F13-E13+1))))) -> 1 | I13: 0.4 | J13: 0.02 | K13: Task
A14: 1.4 | B14: Request DS4 to XS4 copy from ECS | C14: INTL Basis | D14: =IF(K14="Milestone",0,F14-E14+1) -> 2 | E14: 46310 | F14: 46311 | G14: Complete | H14: =IF(G14="Complete",1,IF(OR(G14="Not Started",K14="Milestone",AsOf<E14),0,MIN(0.9,MAX(0,(AsOf-E14+1)/(F14-E14+1))))) -> 1 | I14: 0.4 | J14: 0.04a | K14: Task
A15: 1.5 | B15: Create Maintenance Planner plans | C15: INTL Basis | D15: =IF(K15="Milestone",0,F15-E15+1) -> 2 | E15: 46310 | F15: 46311 | G15: Complete | H15: =IF(G15="Complete",1,IF(OR(G15="Not Started",K15="Milestone",AsOf<E15),0,MIN(0.9,MAX(0,(AsOf-E15+1)/(F15-E15+1))))) -> 1 | J15: 0.05 | K15: Task
A16: 1.6 | B16: Run SI-check and pre-checks | C16: INTL Basis | D16: =IF(K16="Milestone",0,F16-E16+1) -> 7 | E16: 46311 | F16: 46317 | G16: On Track | H16: =IF(G16="Complete",1,IF(OR(G16="Not Started",K16="Milestone",AsOf<E16),0,MIN(0.9,MAX(0,(AsOf-E16+1)/(F16-E16+1))))) -> 0.42857143 | I16: 1.3 | J16: 0.03, 0.16 | K16: Task
A17: 1.7 | B17: Approve plan at Steering | C17: INTL PMO | D17: =IF(K17="Milestone",0,F17-E17+1) -> 1 | E17: 46315 | F17: 46315 | G17: Not Started | H17: =IF(G17="Complete",1,IF(OR(G17="Not Started",K17="Milestone",AsOf<E17),0,MIN(0.9,MAX(0,(AsOf-E17+1)/(F17-E17+1))))) -> 0 | I17: 1.2 | J17: 0.01 | K17: Task
A18: 1.8 | B18: Request remaining copies and upgrades | C18: INTL Basis | D18: =IF(K18="Milestone",0,F18-E18+1) -> 3 | E18: 46314 | F18: 46316 | G18: Not Started | H18: =IF(G18="Complete",1,IF(OR(G18="Not Started",K18="Milestone",AsOf<E18),0,MIN(0.9,MAX(0,(AsOf-E18+1)/(F18-E18+1))))) -> 0 | I18: 1.5 | J18: 0.04, 0.06 | K18: Task
A19: 1.9 | B19: Prepare copy isolation checklist | C19: INTL Basis | D19: =IF(K19="Milestone",0,F19-E19+1) -> 3 | E19: 46314 | F19: 46316 | G19: Not Started | H19: =IF(G19="Complete",1,IF(OR(G19="Not Started",K19="Milestone",AsOf<E19),0,MIN(0.9,MAX(0,(AsOf-E19+1)/(F19-E19+1))))) -> 0 | J19: 0.10 | K19: Task
A20: 1.10 | B20: Line up SAP support and on-call | C20: INTL Basis | D20: =IF(K20="Milestone",0,F20-E20+1) -> 5 | E20: 46314 | F20: 46318 | G20: Not Started | H20: =IF(G20="Complete",1,IF(OR(G20="Not Started",K20="Milestone",AsOf<E20),0,MIN(0.9,MAX(0,(AsOf-E20+1)/(F20-E20+1))))) -> 0 | I20: 1.2 | J20: 0.07, 0.08, 0.09 | K20: Task
A21: 1.11 | B21: Send vendor questions | C21: INTL Basis | D21: =IF(K21="Milestone",0,F21-E21+1) -> 10 | E21: 46314 | F21: 46323 | G21: Not Started | H21: =IF(G21="Complete",1,IF(OR(G21="Not Started",K21="Milestone",AsOf<E21),0,MIN(0.9,MAX(0,(AsOf-E21+1)/(F21-E21+1))))) -> 0 | J21: 0.11 | K21: Task
A22: 1.12 | B22: Check custom code (ATC) | C22: PwC Tech | D22: =IF(K22="Milestone",0,F22-E22+1) -> 5 | E22: 46314 | F22: 46318 | G22: Not Started | H22: =IF(G22="Complete",1,IF(OR(G22="Not Started",K22="Milestone",AsOf<E22),0,MIN(0.9,MAX(0,(AsOf-E22+1)/(F22-E22+1))))) -> 0 | J22: 0.13, 0.14 | K22: Task
A23: 1.13 | B23: Assess Fiori app impact | C23: PwC Tech | D23: =IF(K23="Milestone",0,F23-E23+1) -> 10 | E23: 46314 | F23: 46323 | G23: Not Started | H23: =IF(G23="Complete",1,IF(OR(G23="Not Started",K23="Milestone",AsOf<E23),0,MIN(0.9,MAX(0,(AsOf-E23+1)/(F23-E23+1))))) -> 0 | J23: 0.17, 0.18 | K23: Task
A24: 1.14 | B24: Create data-migration users (SDMI) | C24: INTL Security | D24: =IF(K24="Milestone",0,F24-E24+1) -> 5 | E24: 46314 | F24: 46318 | G24: Not Started | H24: =IF(G24="Complete",1,IF(OR(G24="Not Started",K24="Milestone",AsOf<E24),0,MIN(0.9,MAX(0,(AsOf-E24+1)/(F24-E24+1))))) -> 0 | J24: 0.15 | K24: Task
A25: 1.15 | B25: Prepare CFIN/SLT and GTS runbooks | C25: PwC Functional | D25: =IF(K25="Milestone",0,F25-E25+1) -> 10 | E25: 46314 | F25: 46323 | G25: Not Started | H25: =IF(G25="Complete",1,IF(OR(G25="Not Started",K25="Milestone",AsOf<E25),0,MIN(0.9,MAX(0,(AsOf-E25+1)/(F25-E25+1))))) -> 0 | J25: 0.19, 0.20 | K25: Task
A26: 1.16 | B26: Agree Mock3 rules with Syniti | C26: PwC Data Migration | D26: =IF(K26="Milestone",0,F26-E26+1) -> 2 | E26: 46314 | F26: 46315 | G26: Not Started | H26: =IF(G26="Complete",1,IF(OR(G26="Not Started",K26="Milestone",AsOf<E26),0,MIN(0.9,MAX(0,(AsOf-E26+1)/(F26-E26+1))))) -> 0 | J26: 0.21 | K26: Task
A27: 1.17 | B27: Publish transport rules | C27: INTL Basis | D27: =IF(K27="Milestone",0,F27-E27+1) -> 3 | E27: 46316 | F27: 46318 | G27: Not Started | H27: =IF(G27="Complete",1,IF(OR(G27="Not Started",K27="Milestone",AsOf<E27),0,MIN(0.9,MAX(0,(AsOf-E27+1)/(F27-E27+1))))) -> 0 | I27: 1.7 | J27: 0.12 | K27: Task
A28: 1.18 | B28: Tag regression scripts | C28: INTL Testing | D28: =IF(K28="Milestone",0,F28-E28+1) -> 5 | E28: 46314 | F28: 46318 | G28: Not Started | H28: =IF(G28="Complete",1,IF(OR(G28="Not Started",K28="Milestone",AsOf<E28),0,MIN(0.9,MAX(0,(AsOf-E28+1)/(F28-E28+1))))) -> 0 | J28: 0.22 | K28: Task
A29: 1.19 | B29: ◆ G0 Ready for Sandbox | C29: INTL PMO | D29: =IF(K29="Milestone",0,F29-E29+1) -> 0 | E29: 46317 | F29: 46317 | G29: Not Started | H29: =IF(G29="Complete",1,IF(OR(G29="Not Started",K29="Milestone",AsOf<E29),0,MIN(0.9,MAX(0,(AsOf-E29+1)/(F29-E29+1))))) -> 0 | I29: 1.3, 1.4, 1.5, 1.6, 1.7, 1.8, 1.9 | J29: G0 | K29: Milestone | L29: =IF(L$4=$E29,"◆","") | M29: =IF(M$4=$E29,"◆","") | N29: =IF(N$4=$E29,"◆","") | O29: =IF(O$4=$E29,"◆","") | P29: =IF(P$4=$E29,"◆","") | Q29: =IF(Q$4=$E29,"◆","") | R29: =IF(R$4=$E29,"◆","") | S29: =IF(S$4=$E29,"◆","") | ... CQ29: =IF(CQ$4=$E29,"◆","")
A30: 2 | B30: Sandbox XS4 | D30: =IF(OR(E30="",F30=""),"",F30-E30+1) -> 9 | E30: =MIN(E31:E41) -> 46316 | F30: =MAX(F31:F41) -> 46324 | G30: =IF(COUNTIF(G31:G41,"Blocked")>0,"Blocked",IF(COUNTIF(G31:G41,"At Risk")>0,"At Risk",IF(COUNTIF(G31:G41,"Complete")=ROWS(G31:G41),"Complete",IF(COUNTIF(G31:G41,"Not Started")=ROWS(G31:G41),"Not Started","On Track")))) -> Not Started | H30: =IFERROR(SUMPRODUCT(D31:D41,H31:H41)/SUM(D31:D41),0) -> 0 | K30: Summary
A31: 2.1 | B31: Copy DS4 to XS4 | C31: SAP ECS | D31: =IF(K31="Milestone",0,F31-E31+1) -> 2 | E31: 46316 | F31: 46317 | G31: Not Started | H31: =IF(G31="Complete",1,IF(OR(G31="Not Started",K31="Milestone",AsOf<E31),0,MIN(0.9,MAX(0,(AsOf-E31+1)/(F31-E31+1))))) -> 0 | I31: 1.3, 1.4 | J31: 1.01 | K31: Task
A32: 2.2 | B32: Isolate XS4 | C32: INTL Basis | D32: =IF(K32="Milestone",0,F32-E32+1) -> 1 | E32: 46317 | F32: 46317 | G32: Not Started | H32: =IF(G32="Complete",1,IF(OR(G32="Not Started",K32="Milestone",AsOf<E32),0,MIN(0.9,MAX(0,(AsOf-E32+1)/(F32-E32+1))))) -> 0 | I32: 2.1, 1.9 | J32: 1.02 | K32: Task
A33: 2.3 | B33: Check notes and resubmit SUM request | C33: INTL Basis | D33: =IF(K33="Milestone",0,F33-E33+1) -> 1 | E33: 46317 | F33: 46317 | G33: Not Started | H33: =IF(G33="Complete",1,IF(OR(G33="Not Started",K33="Milestone",AsOf<E33),0,MIN(0.9,MAX(0,(AsOf-E33+1)/(F33-E33+1))))) -> 0 | I33: 2.2 | J33: 1.03 | K33: Task
A34: 2.4 | B34: Upgrade XS4 (downtime Sat 24 Oct) | C34: SAP ECS | D34: =IF(K34="Milestone",0,F34-E34+1) -> 4 | E34: 46317 | F34: 46320 | G34: Not Started | H34: =IF(G34="Complete",1,IF(OR(G34="Not Started",K34="Milestone",AsOf<E34),0,MIN(0.9,MAX(0,(AsOf-E34+1)/(F34-E34+1))))) -> 0 | I34: 2.3, 1.19 | J34: 1.04 | K34: Task
A35: 2.5 | B35: Adjust custom code (SPDD/SPAU) | C35: PwC Tech | D35: =IF(K35="Milestone",0,F35-E35+1) -> 3 | E35: 46319 | F35: 46321 | G35: Not Started | H35: =IF(G35="Complete",1,IF(OR(G35="Not Started",K35="Milestone",AsOf<E35),0,MIN(0.9,MAX(0,(AsOf-E35+1)/(F35-E35+1))))) -> 0 | I35: 2.4SS | J35: 1.05 | K35: Task
A36: 2.6 | B36: Run technical and Fiori checks | C36: INTL Basis | D36: =IF(K36="Milestone",0,F36-E36+1) -> 2 | E36: 46320 | F36: 46321 | G36: Not Started | H36: =IF(G36="Complete",1,IF(OR(G36="Not Started",K36="Milestone",AsOf<E36),0,MIN(0.9,MAX(0,(AsOf-E36+1)/(F36-E36+1))))) -> 0 | I36: 2.4 | J36: 1.06, 1.07 | K36: Task
A37: 2.7 | B37: Update roles (SU25, GRC) | C37: INTL Security | D37: =IF(K37="Milestone",0,F37-E37+1) -> 2 | E37: 46321 | F37: 46322 | G37: Not Started | H37: =IF(G37="Complete",1,IF(OR(G37="Not Started",K37="Milestone",AsOf<E37),0,MIN(0.9,MAX(0,(AsOf-E37+1)/(F37-E37+1))))) -> 0 | I37: 2.6 | J37: 1.08 | K37: Task
A38: 2.8 | B38: Trial SAP note bundle | C38: PwC Tech | D38: =IF(K38="Milestone",0,F38-E38+1) -> 3 | E38: 46321 | F38: 46323 | G38: Not Started | H38: =IF(G38="Complete",1,IF(OR(G38="Not Started",K38="Milestone",AsOf<E38),0,MIN(0.9,MAX(0,(AsOf-E38+1)/(F38-E38+1))))) -> 0 | I38: 2.5 | J38: 1.09 | K38: Task
A39: 2.9 | B39: Test Sandbox (30 tests) | C39: PwC Functional | D39: =IF(K39="Milestone",0,F39-E39+1) -> 3 | E39: 46321 | F39: 46323 | G39: Not Started | H39: =IF(G39="Complete",1,IF(OR(G39="Not Started",K39="Milestone",AsOf<E39),0,MIN(0.9,MAX(0,(AsOf-E39+1)/(F39-E39+1))))) -> 0 | I39: 2.6 | J39: 1.10 | K39: Task
A40: 2.10 | B40: Confirm upgrade windows with ECS | C40: INTL Basis | D40: =IF(K40="Milestone",0,F40-E40+1) -> 1 | E40: 46323 | F40: 46323 | G40: Not Started | H40: =IF(G40="Complete",1,IF(OR(G40="Not Started",K40="Milestone",AsOf<E40),0,MIN(0.9,MAX(0,(AsOf-E40+1)/(F40-E40+1))))) -> 0 | I40: 2.4 | J40: 1.11 | K40: Task
...

Sheet Exec Summary
A1: Executive summary
A2: Edit the yellow cells daily, save, then load this file in the dashboard ("Update data"). The dashboard headline comes from here.
A4: Item | B4: Value
A5: As of | B5: 46313
A6: Overall status | B6: On Track
A7: Headline | B7: Sandbox preparation is completing on plan. XS4 is copied from DS4 on Wed 21 - Thu 22 Oct and upgraded on Sat 24 Oct.
A8: Key message 1 | B8: Done: SAP Notes in DS4, ECS copy request raised, Maintenance Planner plans for every system.
A9: Key message 2 | B9: PwC Tech team aligned; PwC Functional team reviewing the plan before Steering on Tue 20 Oct.
A10: Key message 3 | B10: Production upgrade Sat 21 Nov, before cutover (7 Dec) and go-live (1 Jan 2027).
A11: History note | B11: Thu 15 Oct: approach changed - the Sandbox (XS4) is rebuilt as a copy of DS4 before its upgrade.
A12: Project | B12: Project NorthStar
A13: Upgrade | B13: SAP S/4HANA 2023 FPS02 to SPS06 (RISE with SAP, Private Cloud)
A14: Plan version | B14: v4.0 (18 Oct 2026)
A15: Plan owner | B15: Girish Ogirala (INTL Basis)
A16: Go-live | B16: 46388
A18: Team alignment
A19: Team | B19: Plan alignment | C19: Status | D19: Next step
A20: INTL Basis | B20: Plan owner | C20: On Track | D20: SI-check in DS4 and QS4; isolation checklist; remaining ECS requests Mon 19 Oct
A21: PwC Tech | B21: Aligned | C21: On Track | D21: Custom code check (ATC) and Fiori impact from Mon 19 Oct
A22: PwC Functional | B22: Reviewing | C22: On Track | D22: Review complete Mon 19 Oct; CFIN/SLT and GTS runbooks
A23: SAP ECS | B23: Copy request raised | C23: On Track | D23: Copy DS4 to XS4 Wed 21 - Thu 22 Oct; XS4 upgrade Sat 24 Oct
A25: Asks of leadership
A26: Ask | B26: Detail | C26: By | D26: From
A27: Approve the upgrade plan | B27: Copy approach, five weekend upgrade windows (24 Oct - 21 Nov), gates G0-G5, Plan B/C | C27: 46315 | D27: Steering
A28: Confirm weekend cover | B28: SAP MaxAttention, ECS and the on-call rota for the weekends 24 Oct - 22 Nov | C28: 46317 | D28: Steering / INTL Basis
A30: Plan numbers (calculated from Schedule)
A31: Tasks and gates | B31: =COUNTIFS(Schedule!$K$5:$K$300,"<>Summary",Schedule!$K$5:$K$300,"<>") -> 79
A32: Complete | B32: =COUNTIFS(Schedule!$K$5:$K$300,"<>Summary",Schedule!$G$5:$G$300,"Complete") -> 8
A33: On Track | B33: =COUNTIFS(Schedule!$K$5:$K$300,"<>Summary",Schedule!$G$5:$G$300,"On Track") -> 2
A34: Not Started | B34: =COUNTIFS(Schedule!$K$5:$K$300,"<>Summary",Schedule!$G$5:$G$300,"Not Started") -> 69
A35: At Risk | B35: =COUNTIFS(Schedule!$K$5:$K$300,"<>Summary",Schedule!$G$5:$G$300,"At Risk") -> 0
A36: Blocked | B36: =COUNTIFS(Schedule!$K$5:$K$300,"<>Summary",Schedule!$G$5:$G$300,"Blocked") -> 0
A37: Overdue | B37: =SUMPRODUCT((Schedule!$K$5:$K$300<>"Summary")*(Schedule!$K$5:$K$300<>"")*(Schedule!$G$5:$G$300<>"Complete")*(Schedule!$F$5:$F$300<AsOf)) -> 0
A38: Next gate date | B38: =_xlfn.MINIFS(Schedule!$E$5:$E$300,Schedule!$K$5:$K$300,"Milestone",Schedule!$G$5:$G$300,"<>Complete",Schedule!$E$5:$E$300,">="&AsOf) -> 46317
A39: Next gate | B39: =IFERROR(INDEX(Schedule!$B$5:$B$300,MATCH(1,INDEX((Schedule!$E$5:$E$300=B38)*(Schedule!$K$5:$K$300="Milestone"),0),0)),"") -> ◆ G0 Ready for Sandbox

Sheet Milestones
A1: Milestones and gates
A2: Gate and upgrade rows take their status from the Schedule (column H). Project rows are context from the Plan on a Page.
A4: ID | B4: Date | C4: Milestone | D4: Type | E4: Criteria / notes | F4: Decision owner | G4: Status | H4: Schedule ID
A5: G0 | B5: 46317 | C5: Ready for Sandbox | D5: Gate | E5: Notes 2399707/2502552 in DS4 and transported; SI-check RC < 8 in DS4 and QS4; SRs accepted with windows; MPID per system; copy isolation checklist signed | F5: INTL PMO (Steering) | G5: =IFERROR(INDEX(Schedule!$G$5:$G$300,MATCH($H5,Schedule!$A$5:$A$300,0)),"Not Started") -> Not Started | H5: 1.19
A6: XS4 | B6: 46319 | C6: Sandbox XS4 on SPS06 | D6: Upgrade | E6: Downtime Sat 24 Oct, Sun 25 contingency | F6: SAP ECS / INTL Basis | G6: =IFERROR(INDEX(Schedule!$G$5:$G$300,MATCH($H6,Schedule!$A$5:$A$300,0)),"Not Started") -> Not Started | H6: 2.4
A7: G1 | B7: 46324 | C7: Sandbox sign-off | D7: Gate | E7: XS4 upgrade clean; Sandbox Test Plan "Yes" items passed; SPDD/SPAU and note effort sized; downtime measured; vendor answers received or tracked | F7: INTL PMO (Steering) | G7: =IFERROR(INDEX(Schedule!$G$5:$G$300,MATCH($H7,Schedule!$A$5:$A$300,0)),"Not Started") -> Not Started | H7: 2.11
A8: DS4 | B8: 46326 | C8: Development DS4 on SPS06 | D8: Upgrade | E8: Downtime Sat 31 Oct, Sun 1 Nov contingency; DS5 live as temporary Dev | F8: SAP ECS / INTL Basis | G8: =IFERROR(INDEX(Schedule!$G$5:$G$300,MATCH($H8,Schedule!$A$5:$A$300,0)),"Not Started") -> Not Started | H8: 3.4
A9: G2 | B9: 46330 | C9: Dev ready | D9: Gate | E9: SPDD/SPAU, note and role transports released; no blocking unit-test failure; zero priority-1 ATC findings | F9: INTL PMO (Steering) | G9: =IFERROR(INDEX(Schedule!$G$5:$G$300,MATCH($H9,Schedule!$A$5:$A$300,0)),"Not Started") -> Not Started | H9: 3.11
A10: SIT2 | B10: 46332 | C10: SIT2 ends (QS4-200) | D10: Project | E10: Plan on a Page | F10: Project | G10: Not Started | H10: -
A11: QS4 | B11: 46333 | C11: QA QS4 on SPS06 | D11: Upgrade | E11: Downtime Sat 7 Nov, Sun 8 contingency | F11: SAP ECS / INTL Basis | G11: =IFERROR(INDEX(Schedule!$G$5:$G$300,MATCH($H11,Schedule!$A$5:$A$300,0)),"Not Started") -> Not Started | H11: 4.5
A12: G3 | B12: 46338 | C12: Go for pre-production | D12: Gate | E12: P1 re-run >= 95% pass; zero open Sev1/Sev2 upgrade defects; CFIN, GTS, BTP integrations green; security passed; migration objects load on SPS06 | F12: INTL PMO (Steering) | G12: =IFERROR(INDEX(Schedule!$G$5:$G$300,MATCH($H12,Schedule!$A$5:$A$300,0)),"Not Started") -> Not Started | H12: 4.13
A13: SS4 | B13: 46340 | C13: Pre-production SS4 on SPS06 | D13: Upgrade | E13: Downtime Fri night 13 - Sat 14 Nov, Sun 15 contingency | F13: SAP ECS / INTL Basis | G13: =IFERROR(INDEX(Schedule!$G$5:$G$300,MATCH($H13,Schedule!$A$5:$A$300,0)),"Not Started") -> Not Started | H13: 5.3
A14: G4 | B14: 46345 | C14: Go for production | D14: Gate | E14: SS4 stable; UAT running on SPS06 without upgrade blockers; performance delta acceptable; legacy end-to-end OK | F14: INTL PMO (Steering) | G14: =IFERROR(INDEX(Schedule!$G$5:$G$300,MATCH($H14,Schedule!$A$5:$A$300,0)),"Not Started") -> Not Started | H14: 5.8
A15: PS4 | B15: 46347 | C15: Production PS4 on SPS06 | D15: Upgrade | E15: Downtime Fri night 20 - Sat 21 Nov, Sun 22 contingency | F15: SAP ECS / INTL Basis | G15: =IFERROR(INDEX(Schedule!$G$5:$G$300,MATCH($H15,Schedule!$A$5:$A$300,0)),"Not Started") -> Not Started | H15: 6.2
A16: G5 | B16: 46351 | C16: Upgrade closed | D16: Gate | E16: PS4 technical verification signed; UAT clean on SPS06; open items handed to Go/No-Go | F16: INTL PMO -> Go/No-Go board | G16: =IFERROR(INDEX(Schedule!$G$5:$G$300,MATCH($H16,Schedule!$A$5:$A$300,0)),"Not Started") -> Not Started | H16: 6.5
A17: GNG | B17: 46356 | C17: Go / No-Go (30 Nov - 4 Dec) | D17: Project | E17: Plan on a Page (at UAT end) | F17: Project | G17: Not Started | H17: -
A18: N+1 | B18: 46359 | C18: DS5 / QS5 on SPS06 | D18: Upgrade | E18: DS5 Tue 1 Dec, QS5 Thu 3 Dec | F18: SAP ECS / INTL Basis | G18: =IFERROR(INDEX(Schedule!$G$5:$G$300,MATCH($H18,Schedule!$A$5:$A$300,0)),"Not Started") -> Not Started | H18: 7.2
A19: CUT | B19: 46363 | C19: Cutover starts (7 - 31 Dec) | D19: Project | E19: Plan on a Page | F19: Project | G19: Not Started | H19: -
A20: GL | B20: 46388 | C20: Go-live | D20: Project | E20: Plan on a Page | F20: Project | G20: Not Started | H20: -
A22: Plan B | C22: Plan B (ECS cannot meet a window, or G1 fails): shift the chain by one week - XS4 31 Oct, DS4 7 Nov (after SIT2, so DS5 is not needed for SIT2 fixes), QS4 14 Nov, SS4 21 Nov, PS4 28 Nov (Thanksgiving weekend). G5 moves to Wed 2 Dec, inside the Go/No-Go week; UAT weeks 1-2 run on FPS02 and weeks 3-4 on SPS06.
A23: Plan C | C23: Plan C (G3 fails): SS4 and PS4 stay on FPS02 and go live on FPS02. DS5 and QS5 (FPS02 copies) become the delivery line for fixes to SS4 and PS4; DS4 and QS4 stay on SPS06 as the post-go-live upgrade line. Remaining systems are upgraded after hypercare.

Sheet Detail Plan
A1: Detail plan
A2: Reference detail behind each Schedule row. Status follows the Schedule (column B = Schedule ID). R = Responsible, A = Accountable, C = Consulted. Days = calendar days.
A4: ID | B4: Schedule ID | C4: Phase | D4: Workstream | E4: Task | F4: System(s) | G4: Start | H4: End | I4: Responsible | J4: Accountable | K4: Consulted | L4: Depends on | M4: Deliverable / exit | N4: Source | O4: Status | P4: Notes | Q4: Days | R4: Overdue | S4: BPMN node
A5: H.1 | B5: 0.2 | C5: P0 Prepare Sandbox & prerequisites | D5: TEC - Technical upgrade (Basis / ECS) | E5: Maintenance Planner transaction 1002693650 for XS4 (target SAP S/4HANA 2023 SPS06, SUM 2.0 SP26) | F5: XS4 | G5: 46298 | H5: 46299 | I5: INTL Basis | J5: INTL Basis | K5: SAP ECS | L5: - | M5: Stack file attached to SR 31018471 | N5: MP plan.pdf | O5: =IFERROR(INDEX(Schedule!$G$5:$G$300,MATCH($B5,Schedule!$A$5:$A$300,0)),"Not Started") -> Complete | P5: Plan status Completed; created 3 Oct, modified 4 Oct 2026 | Q5: =IF(AND(ISNUMBER(G5),ISNUMBER(H5)),H5-G5+1,"") -> 2 | R5: =IF(AND(ISNUMBER(H5),O5<>"Complete",H5<AsOf),"Overdue","") | S5: -
A6: H.2 | B6: 0.2 | C6: P0 Prepare Sandbox & prerequisites | D6: TEC - Technical upgrade (Basis / ECS) | E6: SR 31018471 raised: Update Software Version of Application (BASIC_1.5.09), XS4, window 9 Oct 02:45-10:45 UTC | F6: XS4 | G6: 46298 | H6: 46298 | I6: INTL Basis | J6: INTL Basis | K6: SAP ECS | L6: - | M6: SR validated by ECS 5 Oct | N6: SR log | O6: =IFERROR(INDEX(Schedule!$G$5:$G$300,MATCH($B6,Schedule!$A$5:$A$300,0)),"Not Started") -> Complete | P6: SAP for Me also shows Request ID 31018481 for this SR | Q6: =IF(AND(ISNUMBER(G6),ISNUMBER(H6)),H6-G6+1,"") -> 1 | R6: =IF(AND(ISNUMBER(H6),O6<>"Complete",H6<AsOf),"Overdue","") | S6: -
A7: H.3 | B7: 0.3 | C7: P0 Prepare Sandbox & prerequisites | D7: TEC - Technical upgrade (Basis / ECS) | E7: First XS4 update run (SR 31018471) paused at Configuration (12%) by the SI-check: latest version of SAP Note 2502552 needed first; ECS reset SUM on 14 Oct | F7: XS4 | G7: 46302 | H7: 46309 | I7: SAP ECS | J7: INTL Basis | K7: INTL Basis | L7: H.2 | M7: SUM reset; SR 31018471 kept for the rerun after the copy (1.03) | N7: SR log | O7: =IFERROR(INDEX(Schedule!$G$5:$G$300,MATCH($B7,Schedule!$A$5:$A$300,0)),"Not Started") -> Complete | P7: Lesson applied: notes go into DS4 first (0.02), then XS4 is copied from DS4 (H.5) | Q7: =IF(AND(ISNUMBER(G7),ISNUMBER(H7)),H7-G7+1,"") -> 8 | R7: =IF(AND(ISNUMBER(H7),O7<>"Complete",H7<AsOf),"Overdue","") | S7: -
A8: H.4 | B8: 0.1 | C8: P0 Prepare Sandbox & prerequisites | D8: CODE - Custom code, notes, SPDD/SPAU | E8: Side-effect report for MP 1002693650 triaged: 135 in-scope notes (2 HotNews: 3777415, 3563542), 178 conditional | F8: All | G8: 46297 | H8: 46301 | I8: PwC Technical | J8: INTL Basis | K8: PwC Functional | L8: - | M8: SAP_Notes_Side_Effect_Register_SPS06.xlsx | N8: SER | O8: =IFERROR(INDEX(Schedule!$G$5:$G$300,MATCH($B8,Schedule!$A$5:$A$300,0)),"Not Started") -> Complete | P8: Register delivered 6 Oct | Q8: =IF(AND(ISNUMBER(G8),ISNUMBER(H8)),H8-G8+1,"") -> 5 | R8: =IF(AND(ISNUMBER(H8),O8<>"Complete",H8<AsOf),"Overdue","") | S8: -
A9: H.5 | B9: 0.4 | C9: P0 Prepare Sandbox & prerequisites | D9: GOV - Governance & SAP engagement | E9: Approach changed: rebuild the Sandbox XS4 as a copy of DS4, then rerun SUM, so the rehearsal runs on Development code and configuration (decision D1) | F9: DS4 > XS4 | G9: 46310 | H9: 46310 | I9: INTL Basis | J9: INTL Basis | K9: PwC Technical; SAP ECS | L9: H.3 | M9: Sandbox preparation started | N9: USER | O9: =IFERROR(INDEX(Schedule!$G$5:$G$300,MATCH($B9,Schedule!$A$5:$A$300,0)),"Not Started") -> Complete | P9: Sandbox preparation runs from Thu 15 Oct | Q9: =IF(AND(ISNUMBER(G9),ISNUMBER(H9)),H9-G9+1,"") -> 1 | R9: =IF(AND(ISNUMBER(H9),O9<>"Complete",H9<AsOf),"Overdue","") | S9: -
A10: 0.01a | B10: 1.1 | C10: P0 Prepare Sandbox & prerequisites | D10: GOV - Governance & SAP engagement | E10: Align the upgrade plan with the PwC Technical team (copy strategy, SPDD/SPAU, notes, ATC, weekend windows) | F10: - | G10: 46310 | H10: 46311 | I10: INTL Basis | J10: INTL Basis | K10: PwC Technical | L10: H.5 | M10: PwC Technical aligned | N10: USER | O10: =IFERROR(INDEX(Schedule!$G$5:$G$300,MATCH($B10,Schedule!$A$5:$A$300,0)),"Not Started") -> Complete | P10: PwC Technical team aligned (USER, 18 Oct) | Q10: =IF(AND(ISNUMBER(G10),ISNUMBER(H10)),H10-G10+1,"") -> 2 | R10: =IF(AND(ISNUMBER(H10),O10<>"Complete",H10<AsOf),"Overdue","") | S10: -
A11: 0.01b | B11: 1.2 | C11: P0 Prepare Sandbox & prerequisites | D11: GOV - Governance & SAP engagement | E11: PwC Functional teams review the plan: stream impacts, regression scope, CFIN/SLT and GTS runbooks, Sandbox test plan | F11: - | G11: 46311 | H11: 46314 | I11: PwC Functional | J11: INTL Basis | K11: PwC Technical; INTL Test Lead | L11: 0.01a | M11: Review comments closed | N11: USER | O11: =IFERROR(INDEX(Schedule!$G$5:$G$300,MATCH($B11,Schedule!$A$5:$A$300,0)),"Not Started") -> On Track | P11: Review in progress (USER, 18 Oct) | Q11: =IF(AND(ISNUMBER(G11),ISNUMBER(H11)),H11-G11+1,"") -> 4 | R11: =IF(AND(ISNUMBER(H11),O11<>"Complete",H11<AsOf),"Overdue","") | S11: -
A12: 0.01 | B12: 1.7 | C12: P0 Prepare Sandbox & prerequisites | D12: GOV - Governance & SAP engagement | E12: Approve plan v4 at Steering: copy strategy (XS4, DS5, QS5), weekend windows, gates G0-G5, Plan B/C | F12: - | G12: 46315 | H12: 46315 | I12: INTL Basis | J12: INTL PMO | K12: PwC Technical; PwC Functional | L12: 0.01b | M12: Plan v4 baselined; owners named | N12: USER | O12: =IFERROR(INDEX(Schedule!$G$5:$G$300,MATCH($B12,Schedule!$A$5:$A$300,0)),"Not Started") -> Not Started | Q12: =IF(AND(ISNUMBER(G12),ISNUMBER(H12)),H12-G12+1,"") -> 1 | R12: =IF(AND(ISNUMBER(H12),O12<>"Complete",H12<AsOf),"Overdue","") | S12: -
A13: 0.02 | B13: 1.3 | C13: P0 Prepare Sandbox & prerequisites | D13: TEC - Technical upgrade (Basis / ECS) | E13: Implement the latest versions of SAP Notes 2399707 and 2502552 (TCI) in DS4; release the transport to QS4, SS4, PS4 before each SUM. Check the number: 2502552 (the 12 Oct attempt used 2502662) | F13: DS4 > QS4/SS4/PS4 | G13: 46310 | H13: 46311 | I13: INTL Basis | J13: INTL Basis | K13: PwC Technical | L13: H.5 | M13: Notes at latest version in DS4; transport in import queues | N13: UG 2.1, 4.4; SR log | O13: =IFERROR(INDEX(Schedule!$G$5:$G$300,MATCH($B13,Schedule!$A$5:$A$300,0)),"Not Started") -> Complete | P13: UG 2.1: a shared transport must be imported into the next system before its upgrade starts | Q13: =IF(AND(ISNUMBER(G13),ISNUMBER(H13)),H13-G13+1,"") -> 2 | R13: =IF(AND(ISNUMBER(H13),O13<>"Complete",H13<AsOf),"Overdue","") | S13: 1, C2
A14: 0.03 | B14: 1.6 | C14: P0 Prepare Sandbox & prerequisites | D14: TEC - Technical upgrade (Basis / ECS) | E14: Run SI-check /SDF/RC_START_CHECK (target 2023 SPS06) with "Check Consistency for All" in DS4 and QS4; fix RC 8/12; record RC 7 exemptions | F14: DS4, QS4 | G14: 46311 | H14: 46316 | I14: INTL Basis | J14: INTL Basis | K14: PwC Functional | L14: 0.02 | M14: No RC >= 8 open; exemption log | N14: UG 4.4 | O14: =IFERROR(INDEX(Schedule!$G$5:$G$300,MATCH($B14,Schedule!$A$5:$A$300,0)),"Not Started") -> On Track | P14: SUM stops at start on RC 12 and before downtime on RC >= 8 | Q14: =IF(AND(ISNUMBER(G14),ISNUMBER(H14)),H14-G14+1,"") -> 6 | R14: =IF(AND(ISNUMBER(H14),O14<>"Complete",H14<AsOf),"Overdue","") | S14: 1, C2
A15: 0.04a | B15: 1.4 | C15: P0 Prepare Sandbox & prerequisites | D15: GOV - Governance & SAP engagement | E15: Raise the ECS SR for the system copy DS4 > XS4 (copy Wed 21 - Thu 22 Oct) | F15: DS4 > XS4 | G15: 46310 | H15: 46311 | I15: INTL Basis | J15: INTL Basis | K15: SAP ECS | L15: H.5 | M15: Copy SR raised (number in SR Tracker) | N15: USER | O15: =IFERROR(INDEX(Schedule!$G$5:$G$300,MATCH($B15,Schedule!$A$5:$A$300,0)),"Not Started") -> Complete | P15: Raised (USER, 18 Oct) | Q15: =IF(AND(ISNUMBER(G15),ISNUMBER(H15)),H15-G15+1,"") -> 2 | R15: =IF(AND(ISNUMBER(H15),O15<>"Complete",H15<AsOf),"Overdue","") | S15: -
A16: 0.04 | B16: 1.8 | C16: P0 Prepare Sandbox & prerequisites | D16: GOV - Governance & SAP engagement | E16: Raise the remaining ECS SRs with weekend windows: copies DS4>DS5, QS4>QS5; updates DS4, QS4, SS4, PS4, DS5, QS5 (see SR Tracker); request uptime start time explicitly | F16: All | G16: 46314 | H16: 46314 | I16: INTL Basis | J16: INTL Basis | K16: SAP ECS; INTL PMO | L16: 0.05 | M16: SR numbers and confirmed windows in SR Tracker | N16: UG 5; SR log | O16: =IFERROR(INDEX(Schedule!$G$5:$G$300,MATCH($B16,Schedule!$A$5:$A$300,0)),"Not Started") -> Not Started | P16: ECS validated SR 31018471 within 2 days and preparation started 36 h before downtime | Q16: =IF(AND(ISNUMBER(G16),ISNUMBER(H16)),H16-G16+1,"") -> 1 | R16: =IF(AND(ISNUMBER(H16),O16<>"Complete",H16<AsOf),"Overdue","") | S16: 2, C1
A17: 0.05 | B17: 1.5 | C17: P0 Prepare Sandbox & prerequisites | D17: TEC - Technical upgrade (Basis / ECS) | E17: Maintenance Planner: one transaction per system (DS4, QS4, SS4, PS4, DS5, QS5) with the same target stack as 1002693650; attach each MPID to its SR | F17: All | G17: 46310 | H17: 46311 | I17: INTL Basis | J17: INTL Basis | K17: SAP ECS | L17: - | M17: MPID per system; identical target levels | N17: UG 4.2; MP | O17: =IFERROR(INDEX(Schedule!$G$5:$G$300,MATCH($B17,Schedule!$A$5:$A$300,0)),"Not Started") -> Complete | P17: Created (USER, 18 Oct); MP 1002693650 covered XS4 only | Q17: =IF(AND(ISNUMBER(G17),ISNUMBER(H17)),H17-G17+1,"") -> 2 | R17: =IF(AND(ISNUMBER(H17),O17<>"Complete",H17<AsOf),"Overdue","") | S17: 2
A18: 0.06 | B18: 1.8 | C18: P0 Prepare Sandbox & prerequisites | D18: TEC - Technical upgrade (Basis / ECS) | E18: Ask ECS: are HANA 2.00.089.5 (SPS08) and kernel 916 (in the MP download list) applied inside each SUM window, or do they need DB/OS SRs (DB_1.1.11/12, INFRA_1.6.12) with separate downtime? | F18: All | G18: 46314 | H18: 46316 | I18: INTL Basis | J18: INTL Basis | K18: SAP ECS | L18: - | M18: Written ECS answer; windows adjusted if needed | N18: UG 4.3; MP download list | O18: =IFERROR(INDEX(Schedule!$G$5:$G$300,MATCH($B18,Schedule!$A$5:$A$300,0)),"Not Started") -> Not Started | P18: UG 4.3: OS and DB patching need a separate downtime | Q18: =IF(AND(ISNUMBER(G18),ISNUMBER(H18)),H18-G18+1,"") -> 3 | R18: =IF(AND(ISNUMBER(H18),O18<>"Complete",H18<AsOf),"Overdue","") | S18: 2, 9
A19: 0.07 | B19: 1.10 | C19: P0 Prepare Sandbox & prerequisites | D19: GOV - Governance & SAP engagement | E19: SAP MaxAttention: plan safeguarding review, SI-check and side-effect review, escalation path and weekend coverage for 24 Oct - 22 Nov | F19: - | G19: 46314 | H19: 46318 | I19: INTL Basis | J19: INTL Basis | K19: SAP MaxAttention | L19: 0.01b | M19: Review notes; named contacts per weekend | N19: USER | O19: =IFERROR(INDEX(Schedule!$G$5:$G$300,MATCH($B19,Schedule!$A$5:$A$300,0)),"Not Started") -> Not Started | Q19: =IF(AND(ISNUMBER(G19),ISNUMBER(H19)),H19-G19+1,"") -> 5 | R19: =IF(AND(ISNUMBER(H19),O19<>"Complete",H19<AsOf),"Overdue","") | S19: -
A20: 0.08 | B20: 1.10 | C20: P0 Prepare Sandbox & prerequisites | D20: GOV - Governance & SAP engagement | E20: SAP BTP team: confirm actions for AFC, MBC, DRC (Mexico) and Work Zone around each S/4 window; tenant maintenance dates; copies stay disconnected | F20: - | G20: 46314 | H20: 46318 | I20: INTL Basis | J20: INTL Basis | K20: SAP BTP team; PwC Functional | L20: 0.01b | M20: BTP checklist per window | N20: USER | O20: =IFERROR(INDEX(Schedule!$G$5:$G$300,MATCH($B20,Schedule!$A$5:$A$300,0)),"Not Started") -> Not Started | Q20: =IF(AND(ISNUMBER(G20),ISNUMBER(H20)),H20-G20+1,"") -> 5 | R20: =IF(AND(ISNUMBER(H20),O20<>"Complete",H20<AsOf),"Overdue","") | S20: -
A21: 0.09 | B21: 1.10 | C21: P0 Prepare Sandbox & prerequisites | D21: GOV - Governance & SAP engagement | E21: Incident and escalation protocol: SAP for Me priorities, ECS SR contacts, weekend on-call rota (Basis onsite/offshore, PwC, ECS, MaxAttention) | F21: - | G21: 46314 | H21: 46316 | I21: INTL Basis | J21: INTL Basis | K21: INTL PMO; SAP MaxAttention | L21: - | M21: Rota and contact sheet published | N21: USER | O21: =IFERROR(INDEX(Schedule!$G$5:$G$300,MATCH($B21,Schedule!$A$5:$A$300,0)),"Not Started") -> Not Started | P21: Five consecutive weekend windows (24 Oct - 22 Nov) | Q21: =IF(AND(ISNUMBER(G21),ISNUMBER(H21)),H21-G21+1,"") -> 3 | R21: =IF(AND(ISNUMBER(H21),O21<>"Complete",H21<AsOf),"Overdue","") | S21: -
A22: 0.10 | B22: 1.9 | C22: P0 Prepare Sandbox & prerequisites | D22: GOV - Governance & SAP engagement | E22: Copy isolation checklist for XS4, DS5, QS5: GTS, SLT/CFIN, AFC, MBC/banks, DRC/PAC, Work Zone, Ariba, OneSource, OpenText, SailPoint, Syniti, e-mail, printers, jobs | F22: XS4, DS5, QS5 | G22: 46314 | H22: 46316 | I22: INTL Basis | J22: INTL Basis | K22: PwC Functional; PwC Data Migration; INTL SAP Security | L22: - | M22: Checklist with owner per connection | N22: USER | O22: =IFERROR(INDEX(Schedule!$G$5:$G$300,MATCH($B22,Schedule!$A$5:$A$300,0)),"Not Started") -> Not Started | P22: A copy keeps every RFC, port, certificate and job of its source | Q22: =IF(AND(ISNUMBER(G22),ISNUMBER(H22)),H22-G22+1,"") -> 3 | R22: =IF(AND(ISNUMBER(H22),O22<>"Complete",H22<AsOf),"Overdue","") | S22: 4
A23: 0.11 | B23: 1.11 | C23: P0 Prepare Sandbox & prerequisites | D23: GOV - Governance & SAP engagement | E23: Vendor outreach: send the e-mails in "Vendor Questions" (OpenText, Thomson Reuters, SailPoint, Syniti); answers due Wed 28 Oct | F23: - | G23: 46314 | H23: 46323 | I23: INTL Basis | J23: INTL Basis | K23: PwC Functional; PwC Data Migration; Partner vendors | L23: - | M23: Written answers filed | N23: UG 4.2 | O23: =IFERROR(INDEX(Schedule!$G$5:$G$300,MATCH($B23,Schedule!$A$5:$A$300,0)),"Not Started") -> Not Started | P23: UG 4.2: checking third-party add-ons with their vendors is the customer's responsibility | Q23: =IF(AND(ISNUMBER(G23),ISNUMBER(H23)),H23-G23+1,"") -> 10 | R23: =IF(AND(ISNUMBER(H23),O23<>"Complete",H23<AsOf),"Overdue","") | S23: 3
A24: 0.12 | B24: 1.17 | C24: P0 Prepare Sandbox & prerequisites | D24: GOV - Governance & SAP engagement | E24: Publish transport windows A-E and the DS5 dual-maintenance rule; defect tag UPG-SPS06 in qTest/ADO | F24: All | G24: 46316 | H24: 46318 | I24: INTL Basis | J24: INTL PMO | K24: PwC Technical; INTL Test Lead | L24: 0.01 | M24: Rules briefed to developers and testers | N24: UG 3.1 | O24: =IFERROR(INDEX(Schedule!$G$5:$G$300,MATCH($B24,Schedule!$A$5:$A$300,0)),"Not Started") -> Not Started | P24: Release 2 is paused (USER), so dual maintenance covers SIT2, Mock3 and UAT fixes only | Q24: =IF(AND(ISNUMBER(G24),ISNUMBER(H24)),H24-G24+1,"") -> 3 | R24: =IF(AND(ISNUMBER(H24),O24<>"Complete",H24<AsOf),"Overdue","") | S24: 4
A25: 0.13 | B25: 1.12 | C25: P0 Prepare Sandbox & prerequisites | D25: CODE - Custom code, notes, SPDD/SPAU | E25: Confirm a customer package (Z*) exists in DS4; list objects created by manual note corrections (passive deletion risk, Note 2513585) | F25: DS4 | G25: 46314 | H25: 46317 | I25: PwC Technical | J25: PwC Technical | K25: INTL Basis | L25: - | M25: Package confirmed; objects to rescue listed | N25: UG 3.5 | O25: =IFERROR(INDEX(Schedule!$G$5:$G$300,MATCH($B25,Schedule!$A$5:$A$300,0)),"Not Started") -> Not Started | P25: Packages cannot be created during the update | Q25: =IF(AND(ISNUMBER(G25),ISNUMBER(H25)),H25-G25+1,"") -> 4 | R25: =IF(AND(ISNUMBER(H25),O25<>"Complete",H25<AsOf),"Overdue","") | S25: 5
A26: 0.14 | B26: 1.12 | C26: P0 Prepare Sandbox & prerequisites | D26: CODE - Custom code, notes, SPDD/SPAU | E26: Custom code check: import Simplification DB (CCMSIDB via SYCM, Note 2241080), ATC run with baseline against 2023 SPS06 in DS4 | F26: DS4 | G26: 46314 | H26: 46318 | I26: PwC Technical | J26: PwC Technical | K26: INTL Basis | L26: - | M26: ATC findings list; priority-1 items owned | N26: UG 4.5 | O26: =IFERROR(INDEX(Schedule!$G$5:$G$300,MATCH($B26,Schedule!$A$5:$A$300,0)),"Not Started") -> Not Started | P26: Needs SAP_SATC_ADMIN and S_YCM (UG 4.5.1.1) | Q26: =IF(AND(ISNUMBER(G26),ISNUMBER(H26)),H26-G26+1,"") -> 5 | R26: =IF(AND(ISNUMBER(H26),O26<>"Complete",H26<AsOf),"Overdue","") | S26: 5
A27: 0.15 | B27: 1.14 | C27: P0 Prepare Sandbox & prerequisites | D27: SEC - Security, GRC, SailPoint | E27: SDMI users: create via SDM_USER in every client of DS4, QS4, SS4, PS4 (Notes 2664638, 2850918), or tell ECS to create them in SUM | F27: All | G27: 46314 | H27: 46318 | I27: INTL SAP Security | J27: INTL Basis | K27: SAP ECS | L27: - | M27: SDMI user per client or SR instruction | N27: UG 6.1 | O27: =IFERROR(INDEX(Schedule!$G$5:$G$300,MATCH($B27,Schedule!$A$5:$A$300,0)),"Not Started") -> Not Started | P27: Without the user, SDMIs do not start and data is not migrated | Q27: =IF(AND(ISNUMBER(G27),ISNUMBER(H27)),H27-G27+1,"") -> 5 | R27: =IF(AND(ISNUMBER(H27),O27<>"Complete",H27<AsOf),"Overdue","") | S27: 7
A28: 0.16 | B28: 1.6 | C28: P0 Prepare Sandbox & prerequisites | D28: TEC - Technical upgrade (Basis / ECS) | E28: ODP jobs: check own variants of ODQ_CLEANUP / ODQ_DAEMON vs technical job definitions (Note 2677355) | F28: DS4, QS4 | G28: 46314 | H28: 46317 | I28: INTL Basis | J28: INTL Basis | K28: - | L28: - | M28: Decision recorded | N28: UG 4.7 | O28: =IFERROR(INDEX(Schedule!$G$5:$G$300,MATCH($B28,Schedule!$A$5:$A$300,0)),"Not Started") -> On Track | Q28: =IF(AND(ISNUMBER(G28),ISNUMBER(H28)),H28-G28+1,"") -> 4 | R28: =IF(AND(ISNUMBER(H28),O28<>"Complete",H28<AsOf),"Overdue","") | S28: -
A29: 0.17 | B29: 1.13 | C29: P0 Prepare Sandbox & prerequisites | D29: FIO - Fiori, Work Zone, SAP GUI | E29: Fiori Upgrade Impact Analysis (Fiori apps library) for apps in use: UI content moves FPS02 > FPS03 per MP; list deprecated and successor apps | F29: DS4 | G29: 46314 | H29: 46323 | I29: PwC Technical | J29: PwC Technical | K29: INTL Basis | L29: - | M29: App impact list with owner | N29: UG 3.3; MP | O29: =IFERROR(INDEX(Schedule!$G$5:$G$300,MATCH($B29,Schedule!$A$5:$A$300,0)),"Not Started") -> Not Started | P29: MP: SAP Fiori for S/4HANA 2023 02 > 03 (02/2025) FPS; FES 2023 stays 02 | Q29: =IF(AND(ISNUMBER(G29),ISNUMBER(H29)),H29-G29+1,"") -> 10 | R29: =IF(AND(ISNUMBER(H29),O29<>"Complete",H29<AsOf),"Overdue","") | S29: 6
A30: 0.18 | B30: 1.13 | C30: P0 Prepare Sandbox & prerequisites | D30: FIO - Fiori, Work Zone, SAP GUI | E30: SAP GUI: confirm the deployed GUI version supports the target (Notes 147519, 26417) | F30: - | G30: 46314 | H30: 46317 | I30: INTL Basis | J30: INTL Basis | K30: - | L30: - | M30: Confirmation | N30: UG 3.2 | O30: =IFERROR(INDEX(Schedule!$G$5:$G$300,MATCH($B30,Schedule!$A$5:$A$300,0)),"Not Started") -> Not Started | Q30: =IF(AND(ISNUMBER(G30),ISNUMBER(H30)),H30-G30+1,"") -> 4 | R30: =IF(AND(ISNUMBER(H30),O30<>"Complete",H30<AsOf),"Overdue","") | S30: 6
A31: 0.19 | B31: 1.15 | C31: P0 Prepare Sandbox & prerequisites | D31: INT - Integrations (CFIN, GTS, BTP, partners) | E31: CFIN / SLT runbook: suspend and resume replication on QL4 around QS4 and SS4 windows; QL5 repoint plan for QS5; DMIS compatibility confirmed | F31: QL4, QL5 | G31: 46314 | H31: 46323 | I31: PwC Functional | J31: PwC Functional | K31: INTL Basis; SAP MaxAttention | L31: - | M31: Runbook approved | N31: USER | O31: =IFERROR(INDEX(Schedule!$G$5:$G$300,MATCH($B31,Schedule!$A$5:$A$300,0)),"Not Started") -> Not Started | P31: QL4 = SLT for the N line, QL5 = SLT for N+1 (USER) | Q31: =IF(AND(ISNUMBER(G31),ISNUMBER(H31)),H31-G31+1,"") -> 10 | R31: =IF(AND(ISNUMBER(H31),O31<>"Complete",H31<AsOf),"Overdue","") | S31: 4
A32: 0.20 | B32: 1.15 | C32: P0 Prepare Sandbox & prerequisites | D32: INT - Integrations (CFIN, GTS, BTP, partners) | E32: GTS plan: map S/4 client to GTS client (DS4-DG4, QS4-QG4, SS4-QG4/300); plug-in regression scenarios; QG4-300 UAT pause for the SS4 window | F32: DG4, QG4 | G32: 46314 | H32: 46318 | I32: PwC Functional | J32: PwC Functional | K32: INTL Basis; INTL PO / IT Leads | L32: - | M32: GTS connection map and test list | N32: USER | O32: =IFERROR(INDEX(Schedule!$G$5:$G$300,MATCH($B32,Schedule!$A$5:$A$300,0)),"Not Started") -> Not Started | P32: GTS has no pre-production; QG4 client 300 hosts UAT (USER) | Q32: =IF(AND(ISNUMBER(G32),ISNUMBER(H32)),H32-G32+1,"") -> 5 | R32: =IF(AND(ISNUMBER(H32),O32<>"Complete",H32<AsOf),"Overdue","") | S32: 4
A33: 0.21 | B33: 1.16 | C33: P0 Prepare Sandbox & prerequisites | D33: DM - Data migration (Syniti) | E33: Mock3 protection: Mock3 (SS4-100, 19 Oct - 6 Nov) runs fully on FPS02; no SS4 refresh; Syniti connection unchanged; Mock3 fixes via DS5 after 30 Oct | F33: SS4 | G33: 46314 | H33: 46315 | I33: PwC Data Migration | J33: INTL PMO | K33: INTL Basis; Partner vendors | L33: - | M33: Mock3 change rules agreed with Syniti | N33: POAP | O33: =IFERROR(INDEX(Schedule!$G$5:$G$300,MATCH($B33,Schedule!$A$5:$A$300,0)),"Not Started") -> Not Started | P33: No change to the Mock3 environment is required for the upgrade | Q33: =IF(AND(ISNUMBER(G33),ISNUMBER(H33)),H33-G33+1,"") -> 2 | R33: =IF(AND(ISNUMBER(H33),O33<>"Complete",H33<AsOf),"Overdue","") | S33: -
A34: 0.22 | B34: 1.18 | C34: P0 Prepare Sandbox & prerequisites | D34: TST - Testing | E34: Regression set: SIT2 P1 scripts per stream tagged in qTest for the QS4 re-run; Sandbox test plan owners named | F34: - | G34: 46314 | H34: 46318 | I34: INTL Test Lead | J34: INTL Test Lead | K34: PwC Functional | L34: - | M34: Tagged P1 set; Sandbox test owners | N34: USER | O34: =IFERROR(INDEX(Schedule!$G$5:$G$300,MATCH($B34,Schedule!$A$5:$A$300,0)),"Not Started") -> Not Started | P34: No test automation (USER): all regression is manual | Q34: =IF(AND(ISNUMBER(G34),ISNUMBER(H34)),H34-G34+1,"") -> 5 | R34: =IF(AND(ISNUMBER(H34),O34<>"Complete",H34<AsOf),"Overdue","") | S34: 8
A35: G0 | B35: 1.19 | C35: P0 Prepare Sandbox & prerequisites | D35: GOV - Governance & SAP engagement | E35: GATE G0 - Ready for Sandbox: notes in DS4, SI-check clean, SRs accepted, MPIDs, isolation checklist signed | F35: - | G35: 46317 | H35: 46317 | I35: INTL PMO | J35: INTL PMO | K35: INTL Basis; PwC Technical | L35: 0.01, 0.02, 0.03, 0.04a, 0.04, 0.05, 0.06, 0.09, 0.10 | M35: Go for XS4 SUM | N35: UG 2.2 | O35: =IFERROR(INDEX(Schedule!$G$5:$G$300,MATCH($B35,Schedule!$A$5:$A$300,0)),"Not Started") -> Not Started | Q35: =IF(AND(ISNUMBER(G35),ISNUMBER(H35)),H35-G35+1,"") -> 1 | R35: =IF(AND(ISNUMBER(H35),O35<>"Complete",H35<AsOf),"Overdue","") | S35: G0
A36: 1.01 | B36: 2.1 | C36: P1 Sandbox XS4 (copy of DS4) | D36: TEC - Technical upgrade (Basis / ECS) | E36: ECS system copy DS4 > XS4 (XS4 overwritten; SR 31018471 waits for the rerun) | F36: DS4 > XS4 | G36: 46316 | H36: 46317 | I36: SAP ECS | J36: INTL Basis | K36: INTL Basis | L36: 0.02, 0.04a | M36: XS4 = DS4 code and configuration | N36: USER | O36: =IFERROR(INDEX(Schedule!$G$5:$G$300,MATCH($B36,Schedule!$A$5:$A$300,0)),"Not Started") -> Not Started | P36: Taken from a DS4 backup: no DS4 downtime expected (confirm with ECS) | Q36: =IF(AND(ISNUMBER(G36),ISNUMBER(H36)),H36-G36+1,"") -> 2 | R36: =IF(AND(ISNUMBER(H36),O36<>"Complete",H36<AsOf),"Overdue","") | S36: 10
A37: 1.02 | B37: 2.2 | C37: P1 Sandbox XS4 (copy of DS4) | D37: TEC - Technical upgrade (Basis / ECS) | E37: XS4 post-copy: BDLS, disable RFC/ports/certificates per isolation checklist, SCOT, suspend jobs (BTCTRNS1), STMS, lock users | F37: XS4 | G37: 46317 | H37: 46317 | I37: INTL Basis | J37: INTL Basis | K37: PwC Functional | L37: 1.01, 0.10 | M37: Isolation evidence | N37: USER | O37: =IFERROR(INDEX(Schedule!$G$5:$G$300,MATCH($B37,Schedule!$A$5:$A$300,0)),"Not Started") -> Not Started | Q37: =IF(AND(ISNUMBER(G37),ISNUMBER(H37)),H37-G37+1,"") -> 1 | R37: =IF(AND(ISNUMBER(H37),O37<>"Complete",H37<AsOf),"Overdue","") | S37: 10
A38: 1.03 | B38: 2.3 | C38: P1 Sandbox XS4 (copy of DS4) | D38: TEC - Technical upgrade (Basis / ECS) | E38: XS4: confirm 2399707 / 2502552 at latest version, SI-check RC < 8, check modifications (SE95) and update the SPDD/SPAU answers in SR 31018471 (were "No"); send the SR back | F38: XS4 | G38: 46317 | H38: 46317 | I38: INTL Basis | J38: INTL Basis | K38: PwC Technical | L38: 1.02 | M38: SR 31018471 back with ECS | N38: SR log; UG 3.5, 4.4 | O38: =IFERROR(INDEX(Schedule!$G$5:$G$300,MATCH($B38,Schedule!$A$5:$A$300,0)),"Not Started") -> Not Started | P38: The copy brings DS4 modifications into XS4 | Q38: =IF(AND(ISNUMBER(G38),ISNUMBER(H38)),H38-G38+1,"") -> 1 | R38: =IF(AND(ISNUMBER(H38),O38<>"Complete",H38<AsOf),"Overdue","") | S38: 11, C1, C2
A39: 1.04 | B39: 2.4 | C39: P1 Sandbox XS4 (copy of DS4) | D39: TEC - Technical upgrade (Basis / ECS) | E39: ECS SUM on XS4: uptime Thu 22 - Fri 23 Oct (dev lock set automatically); downtime Sat 24 Oct (Sun 25 contingency) | F39: XS4 | G39: 46317 | H39: 46320 | I39: SAP ECS | J39: INTL Basis | K39: INTL Basis | L39: 1.03, G0 | M39: XS4 on SPS06; runtime and downtime measured | N39: UG 5; SR log | O39: =IFERROR(INDEX(Schedule!$G$5:$G$300,MATCH($B39,Schedule!$A$5:$A$300,0)),"Not Started") -> Not Started | P39: First run planned 8 h downtime (SR window) | Q39: =IF(AND(ISNUMBER(G39),ISNUMBER(H39)),H39-G39+1,"") -> 4 | R39: =IF(AND(ISNUMBER(H39),O39<>"Complete",H39<AsOf),"Overdue","") | S39: 11, C3, C7
A40: 1.05 | B40: 2.5 | C40: P1 Sandbox XS4 (copy of DS4) | D40: CODE - Custom code, notes, SPDD/SPAU | E40: XS4 SPDD (during SUM), SPAU, then SPAU_ENH: prototype and size the DS4 adjustment | F40: XS4 | G40: 46319 | H40: 46321 | I40: PwC Technical | J40: PwC Technical | K40: INTL Basis | L40: 1.04 SS | M40: Worklist and effort for DS4 | N40: UG 3.5 | O40: =IFERROR(INDEX(Schedule!$G$5:$G$300,MATCH($B40,Schedule!$A$5:$A$300,0)),"Not Started") -> Not Started | P40: SPAU_ENH only after SPDD/SPAU (UG 3.5) | Q40: =IF(AND(ISNUMBER(G40),ISNUMBER(H40)),H40-G40+1,"") -> 3 | R40: =IF(AND(ISNUMBER(H40),O40<>"Complete",H40<AsOf),"Overdue","") | S40: 11, C5, C8
A41: 1.06 | B41: 2.6 | C41: P1 Sandbox XS4 (copy of DS4) | D41: TEC - Technical upgrade (Basis / ECS) | E41: XS4 technical checks: SICK, SM21, ST22, SM37, SM59, STMS, SMICM, SGEN, component levels vs MP, SDM_MON | F41: XS4 | G41: 46320 | H41: 46321 | I41: INTL Basis | J41: INTL Basis | K41: SAP ECS | L41: 1.04 | M41: Checklist signed | N41: UG 6.1 | O41: =IFERROR(INDEX(Schedule!$G$5:$G$300,MATCH($B41,Schedule!$A$5:$A$300,0)),"Not Started") -> Not Started | Q41: =IF(AND(ISNUMBER(G41),ISNUMBER(H41)),H41-G41+1,"") -> 2 | R41: =IF(AND(ISNUMBER(H41),O41<>"Complete",H41<AsOf),"Overdue","") | S41: 11, C9
...

Sheet Systems
A1: System landscape
A2: N = go-live line, N+1 = DS5/QS5 copies (fallback until G4). Update "Current level" to SPS06 when a system is done.
A4: SID | B4: Role | C4: Line | D4: Clients | E4: Current level | F4: Target level | G4: Copy | H4: Upgrade window | I4: SR | J4: Connected to | K4: Status | L4: Notes | M4: Copy date | N4: Downtime date
A5: XS4 | B5: Sandbox (rehearsal) | C5: Sandbox | D5: tbc | E5: FPS02 | F5: SPS06 | G5: Copy of DS4, 21-22 Oct | H5: Sat 24 Oct | I5: SR 31018471 | J5: Isolated after copy | K5: On Track | L5: Prep on track since 15 Oct; copy SR raised; SR 31018471 reused for the SUM rerun | M5: 46316 | N5: 46319
A6: DS4 | B6: Development | C6: N (go-live line) | D6: 110 | E6: FPS02 | F6: SPS06 | G6: - | H6: Sat 31 Oct | I6: tbc | J6: DG4; dev BTP tenants | K6: Not Started | L6: Dev lock from Fri 30 Oct (SUM uptime) | N6: 46326
A7: DS5 | B7: Temporary Dev / N+1 Dev | C7: N+1 (fallback) | D7: tbc | E7: FPS02 | F7: SPS06 (1 Dec) | G7: Copy of DS4, 27-28 Oct | H7: Tue 1 Dec | I7: tbc | J7: Isolated; TMS to QS4/SS4 (FPS02 fixes) and QS5 | K7: Not Started | L7: Fallback until G4 | M7: 46322 | N7: 46357
A8: QS4 | B8: QA (SIT) | C8: N (go-live line) | D8: 100, 200 | E8: FPS02 | F8: SPS06 | G8: - | H8: Sat 7 Nov | I8: tbc | J8: QG4; QL4 (SLT); QA BTP tenants; legacy | K8: Not Started | L8: SIT2 in client 200 until 6 Nov | N8: 46333
A9: QS5 | B9: Temporary QA / N+1 QA | C9: N+1 (fallback) | D9: tbc | E9: FPS02 | F9: SPS06 (3 Dec) | G9: Copy of QS4, 4-5 Nov | H9: Thu 3 Dec | I9: tbc | J9: Isolated; QL5 (SLT) repoint | K9: Not Started | L9: Fallback until G4 | M9: 46330 | N9: 46359
A10: SS4 | B10: Pre-production (UAT) | C10: N (go-live line) | D10: 100 | E10: FPS02 | F10: SPS06 | G10: - | H10: Fri-Sat 13-14 Nov | I10: tbc | J10: QG4-300 (GTS UAT); SLT; BTP; legacy | K10: Not Started | L10: Mock3 + performance test to 6 Nov; UAT from 9 Nov | N10: 46340
A11: PS4 | B11: Production | C11: N (go-live line) | D11: tbc | E11: FPS02 | F11: SPS06 | G11: - | H11: Fri-Sat 20-21 Nov | I11: tbc | J11: Production endpoints (pre-cutover) | K11: Not Started | L11: Cutover 7-31 Dec; go-live 1 Jan 2027 | N11: 46347
A12: QL4 | B12: SLT server for Central Finance | C12: N | D12: - | E12: not changed | F12: not changed | G12: - | H12: Suspend/resume around QS4 and SS4 | I12: - | J12: QS4 (CFIN) | K12: Not Started | L12: Confirm DMIS compatibility
A13: QL5 | B13: SLT server for Central Finance | C13: N+1 | D13: - | E13: not changed | F13: not changed | G13: - | H13: Repoint to QS5 after copy | I13: - | J13: QS5 (CFIN) | K13: Not Started
A14: DG4 | B14: SAP GTS Development | C14: GTS | D14: tbc | E14: not changed | F14: not changed | G14: - | H14: Paused during DS4 window | I14: - | J14: DS4 | K14: Not Started | L14: GTS release to confirm
A15: QG4 | B15: SAP GTS QA (client 300 = UAT) | C15: GTS | D15: 300 (UAT) + SIT client tbc | E15: not changed | F15: not changed | G15: - | H15: Paused during QS4 and SS4 windows | I15: - | J15: QS4; SS4 (client 300) | K15: Not Started | L15: No GTS pre-production exists
A16: BTP | B16: AFC, MBC, DRC (MX), Work Zone Standard | C16: SaaS | D16: - | E16: SAP-managed | F16: SAP-managed | G16: - | H16: Connection checks after each window | I16: - | J16: DS4, QS4, SS4, PS4 | K16: Not Started | L16: Copies stay disconnected

Sheet SR Tracker
A1: SAP ECS service requests
A2: Service identifiers from the SR form and the Upgrade Guide (UG 2.1, 3.5, 4.2, 4.3). Copy SR identifiers to be confirmed from the ECS catalog.
A4: SR number | B4: System | C4: Service identifier | D4: Purpose | E4: Window | F4: SAP status | G4: Status | H4: Owner | I4: Next action | J4: Raised on
A5: 31018471 | B5: XS4 | C5: BASIC_1.5.09 Update Software Version of Application (non-chargeable) | D5: XS4 FPS02 > SPS06, MP 1002693650 | E5: New: uptime Thu 22 - Fri 23 Oct, downtime Sat 24 Oct (first window was 9 Oct 02:45-10:45 UTC) | F5: Customer Action (14 Oct) | G5: On Track | H5: INTL Basis | I5: After copy (1.01) and note check (1.03): update SPDD/SPAU answers and new window; send back to ECS | J5: 46298
A6: raised (add no.) | B6: DS4 > XS4 | C6: System copy (identifier per ECS catalog) | D6: Sandbox equal to current DS4 scope | E6: Wed 21 - Thu 22 Oct | F6: - | G6: On Track | H6: INTL Basis | I6: Confirm the copy start time with ECS
A7: to raise | B7: DS4 > DS5 | C7: System copy (per ECS catalog) | D7: Temporary Dev on FPS02 (fallback) | E7: Tue 27 - Wed 28 Oct | F7: - | G7: Not Started | H7: INTL Basis | I7: Raise Mon 19 Oct
A8: to raise | B8: QS4 > QS5 | C8: System copy (per ECS catalog) | D8: Temporary QA on FPS02 (fallback) | E8: Wed 4 - Thu 5 Nov | F8: - | G8: Not Started | H8: INTL Basis | I8: Raise Mon 19 Oct
A9: to raise | B9: DS4 | C9: BASIC_1.5.09 | D9: DS4 FPS02 > SPS06 (SPDD/SPAU here) | E9: Uptime Fri 30 Oct; downtime Sat 31 Oct | F9: - | G9: Not Started | H9: INTL Basis | I9: Raise Mon 19 Oct with DS4 MPID
A10: to raise | B10: QS4 | C10: BASIC_1.5.09 | D10: QS4 FPS02 > SPS06 (reuse DS4 transports) | E10: Downtime Sat 7 Nov | F10: - | G10: Not Started | H10: INTL Basis | I10: Raise Mon 19 Oct; add SPDD/SPAU transport IDs after DS4
A11: to raise | B11: SS4 | C11: BASIC_1.5.09 | D11: SS4 FPS02 > SPS06 | E11: Downtime Fri night 13 - Sat 14 Nov | F11: - | G11: Not Started | H11: INTL Basis | I11: Raise Mon 19 Oct
A12: to raise | B12: PS4 | C12: BASIC_1.5.09 | D12: PS4 FPS02 > SPS06 | E12: Downtime Fri night 20 - Sat 21 Nov | F12: - | G12: Not Started | H12: INTL Basis | I12: Raise Mon 19 Oct
A13: to raise | B13: DS5 | C13: BASIC_1.5.09 | D13: DS5 FPS02 > SPS06 after G4 | E13: Tue 1 Dec | F13: - | G13: Not Started | H13: INTL Basis | I13: Raise after G4 (19 Nov)
A14: to raise | B14: QS5 | C14: BASIC_1.5.09 | D14: QS5 FPS02 > SPS06 after G4 | E14: Thu 3 Dec | F14: - | G14: Not Started | H14: INTL Basis | I14: Raise after G4 (19 Nov)
A15: if needed | B15: All | C15: DB_1.1.11 / DB_1.1.12 (HANA), INFRA_1.6.12 (OS) | D15: Only if ECS requires separate DB/OS updates (task 0.06) | E15: Separate downtime (UG 4.3) | F15: - | G15: Not Started | H15: INTL Basis | I15: Decide on ECS answer
A16: optional | B16: All | C16: TO_NWABAP_1.5.08 (billable upgrade package) | D16: ECS performs SPDD/SPAU steps | E16: - | F16: - | G16: Not Started | H16: INTL Basis | I16: Decision D-O5
A17: optional | B17: All | C17: BASIC_1.5.03 (billable CAS) | D17: ECS performs application notes or Fiori follow-ups | E17: - | F17: - | G17: Not Started | H17: INTL Basis | I17: Decision D-O4

Sheet RAID
A1: Risks, assumptions, issues, decisions
A2: Rating: High / Medium / Low. Status: Open / Closed.
A4: ID | B4: Type | C4: Description | D4: Impact | E4: Rating | F4: Mitigation / response | G4: Owner | H4: Due | I4: Status
A5: I1 | B5: Issue | C5: First XS4 update run paused by the SI-check (latest version of Note 2502552 needed); ECS reset SUM 14 Oct | D5: Sandbox rehearsal rescheduled to Sat 24 Oct | E5: Low | F5: Closed by the approach change on 15 Oct (D1): notes in DS4 (0.02, done), copy DS4 to XS4 (1.01), SI-check, SR 31018471 back to ECS (1.03) | G5: INTL Basis | H5: 46310 | I5: Closed
A6: I2 | B6: Issue | C6: Maintenance Plan 1002693650 covered XS4 only | D6: No stack file for other systems | E6: Low | F6: Closed: MP transaction per system created (0.05, done) | G6: INTL Basis | H6: 46311 | I6: Closed
A7: I3 | B7: Issue | C7: Note number check in SR updates (2502662 was entered instead of 2502552 on 12 Oct) | D7: Wrong note attempted | E7: Low | F7: Closed: four-eyes check of note numbers in every SR update | G7: INTL Basis | H7: 46310 | I7: Closed
A8: R1 | B8: Risk | C8: ECS cannot schedule three copies and six SUM runs on the requested dates | D8: Chain slips | E8: High | F8: Copy SR for XS4 raised; remaining SRs Mon 19 Oct; MaxAttention escalation; Plan B (+1 week) | G8: INTL Basis | H8: 46318 | I8: Open
A9: R2 | B9: Risk | C9: SAP updates Note 2502552 between systems and the SI-check pauses SUM | D9: Window lost | E9: High | F9: Check the note version 48 h before each window; re-run SI-check | G9: INTL Basis | H9: 46346 | I9: Open
A10: R3 | B10: Risk | C10: Copies (XS4, DS5, QS5) send data to GTS, SLT, MBC/banks, DRC/PAC, Ariba, OneSource, SailPoint | D10: Duplicate or false business messages | E10: High | F10: Isolation checklist (0.10) executed and evidenced before any user logs on | G10: INTL Basis | H10: 46332 | I10: Open
A11: R4 | B11: Risk | C11: Five consecutive weekend windows (24 Oct - 22 Nov) for a 3-person Basis team | D11: Fatigue, errors | E11: High | F11: Rota across onsite/offshore; ECS + MaxAttention cover; no Basis change work on weekdays after a window | G11: INTL Basis | H11: 46316 | I11: Open
A12: R5 | B12: Risk | C12: Dual maintenance DS5/DS4: a fix applied in one system only | D12: Regression at cutover | E12: Medium | F12: Retrofit log reconciled daily (2.10); Release 2 paused | G12: PwC Technical | H12: 46339 | I12: Open
A13: R6 | B13: Risk | C13: QS4 regression window is 4 days (9-12 Nov) | D13: Defects reach SS4 | E13: High | F13: P1 scripts only; FPS02 baseline; TR onsite the same week; Sandbox evidence first | G13: INTL Test Lead | H13: 46338 | I13: Open
A14: R7 | B14: Risk | C14: UAT week 1 on FPS02, weeks 2-4 on SPS06 | D14: Defect attribution | E14: Medium | F14: Tag UPG-SPS06; compare against QS4 results | G14: INTL Test Lead | H14: 46342 | I14: Open
A15: R8 | B15: Risk | C15: Mock3 runs on FPS02; cutover loads run on SPS06 | D15: Load failures at cutover | E15: Medium | F15: Syniti sample loads on SPS06 in QS4-100 (3.10); Syniti questions | G15: PwC Data Migration | H15: 46337 | I15: Open
A16: R9 | B16: Risk | C16: Partner confirmations (OpenText, SailPoint, Syniti, TR) not received before G1 / G3 | D16: Unsupported combination | E16: High | F16: E-mails sent 19-20 Oct; answers due 28 Oct; hold at G3 if open | G16: INTL Basis | H16: 46323 | I16: Open
... A21: R14 | B21: Risk | C21: New side effects published after SPS06 is installed | D21: Unexpected defects | E21: Low | F21: Weekly side-effect watch (7.01) | G21: PwC Technical | H21: 46388 | I21: Open
A22: A1 | B22: Assumption | C22: Project dates per Plan on a Page (9/21) and user updates: SIT2 28 Sep - 6 Nov (QS4-200); Mock3 19 Oct - 6 Nov and performance test 14 Oct - 6 Nov (SS4-100); UAT 9 Nov - 4 Dec (SS4-100); Go/No-Go at UAT end; cutover 7 - 31 Dec; go-live 1 Jan 2027 | D22: - | E22: - | F22: - | G22: INTL PMO | I22: Open
A23: A2 | B23: Assumption | C23: Downtime per system is about 8 h (XS4 SR window); actual duration is measured in XS4 (1.11) | D23: - | E23: - | F23: - | G23: INTL Basis | I23: Open
A24: A3 | B24: Assumption | C24: Copies are taken from backups, so DS4 and QS4 stay available during the copy (ECS to confirm) | D24: - | E24: - | F24: - | G24: INTL Basis | I24: Open
A25: A4 | B25: Assumption | C25: No test automation; all regression is manual (USER) | D25: - | E25: - | F25: - | G25: INTL Test Lead | I25: Open
A26: A5 | B26: Assumption | C26: Release 2 is paused (USER); N+1 activity is limited to fallback and fixes | D26: - | E26: - | F26: - | G26: INTL PMO | I26: Open
A27: A6 | B27: Assumption | C27: PS4 holds no business data before cutover (7 Dec) | D27: - | E27: - | F27: - | G27: INTL PMO | I27: Open
